[2023-02-23 01:53:53,023] {processor.py:153} INFO - Started process (PID=188) to work on /opt/airflow/dags/xray_test_dag.py
[2023-02-23 01:53:53,023] {processor.py:641} INFO - Processing file /opt/airflow/dags/xray_test_dag.py for tasks to queue
[2023-02-23 01:53:53,024] {logging_mixin.py:115} INFO - [2023-02-23 01:53:53,024] {dagbag.py:507} INFO - Filling up the DagBag from /opt/airflow/dags/xray_test_dag.py
[2023-02-23 01:53:53,047] {logging_mixin.py:115} INFO - [2023-02-23 01:53:53,044] {dagbag.py:320} ERROR - Failed to import: /opt/airflow/dags/xray_test_dag.py
Traceback (most recent call last):
  File "/home/airflow/.local/lib/python3.7/site-packages/airflow/models/dagbag.py", line 317, in parse
    loader.exec_module(new_module)
  File "<frozen importlib._bootstrap_external>", line 728, in exec_module
  File "<frozen importlib._bootstrap>", line 219, in _call_with_frames_removed
  File "/opt/airflow/dags/xray_test_dag.py", line 11, in <module>
    catchup=False,
TypeError: __init__() got an unexpected keyword argument 'schedule'
[2023-02-23 01:53:53,048] {processor.py:653} WARNING - No viable dags retrieved from /opt/airflow/dags/xray_test_dag.py
[2023-02-23 01:53:53,078] {processor.py:161} INFO - Processing /opt/airflow/dags/xray_test_dag.py took 0.058 seconds
[2023-02-23 01:54:23,126] {processor.py:153} INFO - Started process (PID=193) to work on /opt/airflow/dags/xray_test_dag.py
[2023-02-23 01:54:23,126] {processor.py:641} INFO - Processing file /opt/airflow/dags/xray_test_dag.py for tasks to queue
[2023-02-23 01:54:23,127] {logging_mixin.py:115} INFO - [2023-02-23 01:54:23,127] {dagbag.py:507} INFO - Filling up the DagBag from /opt/airflow/dags/xray_test_dag.py
[2023-02-23 01:54:23,143] {logging_mixin.py:115} INFO - [2023-02-23 01:54:23,137] {dagbag.py:320} ERROR - Failed to import: /opt/airflow/dags/xray_test_dag.py
Traceback (most recent call last):
  File "/home/airflow/.local/lib/python3.7/site-packages/airflow/models/dagbag.py", line 317, in parse
    loader.exec_module(new_module)
  File "<frozen importlib._bootstrap_external>", line 728, in exec_module
  File "<frozen importlib._bootstrap>", line 219, in _call_with_frames_removed
  File "/opt/airflow/dags/xray_test_dag.py", line 11, in <module>
    catchup=False,
TypeError: __init__() got an unexpected keyword argument 'schedule'
[2023-02-23 01:54:23,144] {processor.py:653} WARNING - No viable dags retrieved from /opt/airflow/dags/xray_test_dag.py
[2023-02-23 01:54:23,167] {processor.py:161} INFO - Processing /opt/airflow/dags/xray_test_dag.py took 0.043 seconds
[2023-02-23 01:54:53,283] {processor.py:153} INFO - Started process (PID=198) to work on /opt/airflow/dags/xray_test_dag.py
[2023-02-23 01:54:53,283] {processor.py:641} INFO - Processing file /opt/airflow/dags/xray_test_dag.py for tasks to queue
[2023-02-23 01:54:53,284] {logging_mixin.py:115} INFO - [2023-02-23 01:54:53,284] {dagbag.py:507} INFO - Filling up the DagBag from /opt/airflow/dags/xray_test_dag.py
[2023-02-23 01:54:53,299] {logging_mixin.py:115} INFO - [2023-02-23 01:54:53,296] {dagbag.py:320} ERROR - Failed to import: /opt/airflow/dags/xray_test_dag.py
Traceback (most recent call last):
  File "/home/airflow/.local/lib/python3.7/site-packages/airflow/models/dagbag.py", line 317, in parse
    loader.exec_module(new_module)
  File "<frozen importlib._bootstrap_external>", line 728, in exec_module
  File "<frozen importlib._bootstrap>", line 219, in _call_with_frames_removed
  File "/opt/airflow/dags/xray_test_dag.py", line 11, in <module>
    catchup=False,
TypeError: __init__() got an unexpected keyword argument 'schedule'
[2023-02-23 01:54:53,300] {processor.py:653} WARNING - No viable dags retrieved from /opt/airflow/dags/xray_test_dag.py
[2023-02-23 01:54:53,318] {processor.py:161} INFO - Processing /opt/airflow/dags/xray_test_dag.py took 0.037 seconds
[2023-02-23 01:55:23,385] {processor.py:153} INFO - Started process (PID=203) to work on /opt/airflow/dags/xray_test_dag.py
[2023-02-23 01:55:23,386] {processor.py:641} INFO - Processing file /opt/airflow/dags/xray_test_dag.py for tasks to queue
[2023-02-23 01:55:23,398] {logging_mixin.py:115} INFO - [2023-02-23 01:55:23,398] {dagbag.py:507} INFO - Filling up the DagBag from /opt/airflow/dags/xray_test_dag.py
[2023-02-23 01:55:23,414] {logging_mixin.py:115} INFO - [2023-02-23 01:55:23,411] {dagbag.py:320} ERROR - Failed to import: /opt/airflow/dags/xray_test_dag.py
Traceback (most recent call last):
  File "/home/airflow/.local/lib/python3.7/site-packages/airflow/models/dagbag.py", line 317, in parse
    loader.exec_module(new_module)
  File "<frozen importlib._bootstrap_external>", line 728, in exec_module
  File "<frozen importlib._bootstrap>", line 219, in _call_with_frames_removed
  File "/opt/airflow/dags/xray_test_dag.py", line 11, in <module>
    catchup=False,
TypeError: __init__() got an unexpected keyword argument 'schedule'
[2023-02-23 01:55:23,415] {processor.py:653} WARNING - No viable dags retrieved from /opt/airflow/dags/xray_test_dag.py
[2023-02-23 01:55:23,431] {processor.py:161} INFO - Processing /opt/airflow/dags/xray_test_dag.py took 0.048 seconds
[2023-02-23 01:55:53,503] {processor.py:153} INFO - Started process (PID=208) to work on /opt/airflow/dags/xray_test_dag.py
[2023-02-23 01:55:53,504] {processor.py:641} INFO - Processing file /opt/airflow/dags/xray_test_dag.py for tasks to queue
[2023-02-23 01:55:53,504] {logging_mixin.py:115} INFO - [2023-02-23 01:55:53,504] {dagbag.py:507} INFO - Filling up the DagBag from /opt/airflow/dags/xray_test_dag.py
[2023-02-23 01:55:53,520] {logging_mixin.py:115} INFO - [2023-02-23 01:55:53,517] {dagbag.py:320} ERROR - Failed to import: /opt/airflow/dags/xray_test_dag.py
Traceback (most recent call last):
  File "/home/airflow/.local/lib/python3.7/site-packages/airflow/models/dagbag.py", line 317, in parse
    loader.exec_module(new_module)
  File "<frozen importlib._bootstrap_external>", line 728, in exec_module
  File "<frozen importlib._bootstrap>", line 219, in _call_with_frames_removed
  File "/opt/airflow/dags/xray_test_dag.py", line 11, in <module>
    catchup=False,
TypeError: __init__() got an unexpected keyword argument 'schedule'
[2023-02-23 01:55:53,521] {processor.py:653} WARNING - No viable dags retrieved from /opt/airflow/dags/xray_test_dag.py
[2023-02-23 01:55:53,538] {processor.py:161} INFO - Processing /opt/airflow/dags/xray_test_dag.py took 0.037 seconds
[2023-02-23 01:56:23,618] {processor.py:153} INFO - Started process (PID=213) to work on /opt/airflow/dags/xray_test_dag.py
[2023-02-23 01:56:23,619] {processor.py:641} INFO - Processing file /opt/airflow/dags/xray_test_dag.py for tasks to queue
[2023-02-23 01:56:23,620] {logging_mixin.py:115} INFO - [2023-02-23 01:56:23,620] {dagbag.py:507} INFO - Filling up the DagBag from /opt/airflow/dags/xray_test_dag.py
[2023-02-23 01:56:23,637] {logging_mixin.py:115} INFO - [2023-02-23 01:56:23,634] {dagbag.py:320} ERROR - Failed to import: /opt/airflow/dags/xray_test_dag.py
Traceback (most recent call last):
  File "/home/airflow/.local/lib/python3.7/site-packages/airflow/models/dagbag.py", line 317, in parse
    loader.exec_module(new_module)
  File "<frozen importlib._bootstrap_external>", line 728, in exec_module
  File "<frozen importlib._bootstrap>", line 219, in _call_with_frames_removed
  File "/opt/airflow/dags/xray_test_dag.py", line 11, in <module>
    catchup=False,
TypeError: __init__() got an unexpected keyword argument 'schedule'
[2023-02-23 01:56:23,638] {processor.py:653} WARNING - No viable dags retrieved from /opt/airflow/dags/xray_test_dag.py
[2023-02-23 01:56:23,667] {processor.py:161} INFO - Processing /opt/airflow/dags/xray_test_dag.py took 0.051 seconds
[2023-02-23 01:56:53,726] {processor.py:153} INFO - Started process (PID=218) to work on /opt/airflow/dags/xray_test_dag.py
[2023-02-23 01:56:53,726] {processor.py:641} INFO - Processing file /opt/airflow/dags/xray_test_dag.py for tasks to queue
[2023-02-23 01:56:53,727] {logging_mixin.py:115} INFO - [2023-02-23 01:56:53,727] {dagbag.py:507} INFO - Filling up the DagBag from /opt/airflow/dags/xray_test_dag.py
[2023-02-23 01:56:53,742] {logging_mixin.py:115} INFO - [2023-02-23 01:56:53,740] {dagbag.py:320} ERROR - Failed to import: /opt/airflow/dags/xray_test_dag.py
Traceback (most recent call last):
  File "/home/airflow/.local/lib/python3.7/site-packages/airflow/models/dagbag.py", line 317, in parse
    loader.exec_module(new_module)
  File "<frozen importlib._bootstrap_external>", line 728, in exec_module
  File "<frozen importlib._bootstrap>", line 219, in _call_with_frames_removed
  File "/opt/airflow/dags/xray_test_dag.py", line 11, in <module>
    catchup=False,
TypeError: __init__() got an unexpected keyword argument 'schedule'
[2023-02-23 01:56:53,743] {processor.py:653} WARNING - No viable dags retrieved from /opt/airflow/dags/xray_test_dag.py
[2023-02-23 01:56:53,772] {processor.py:161} INFO - Processing /opt/airflow/dags/xray_test_dag.py took 0.049 seconds
[2023-02-23 01:57:23,862] {processor.py:153} INFO - Started process (PID=223) to work on /opt/airflow/dags/xray_test_dag.py
[2023-02-23 01:57:23,862] {processor.py:641} INFO - Processing file /opt/airflow/dags/xray_test_dag.py for tasks to queue
[2023-02-23 01:57:23,863] {logging_mixin.py:115} INFO - [2023-02-23 01:57:23,863] {dagbag.py:507} INFO - Filling up the DagBag from /opt/airflow/dags/xray_test_dag.py
[2023-02-23 01:57:23,878] {logging_mixin.py:115} INFO - [2023-02-23 01:57:23,876] {dagbag.py:320} ERROR - Failed to import: /opt/airflow/dags/xray_test_dag.py
Traceback (most recent call last):
  File "/home/airflow/.local/lib/python3.7/site-packages/airflow/models/dagbag.py", line 317, in parse
    loader.exec_module(new_module)
  File "<frozen importlib._bootstrap_external>", line 728, in exec_module
  File "<frozen importlib._bootstrap>", line 219, in _call_with_frames_removed
  File "/opt/airflow/dags/xray_test_dag.py", line 11, in <module>
    catchup=False,
TypeError: __init__() got an unexpected keyword argument 'schedule'
[2023-02-23 01:57:23,879] {processor.py:653} WARNING - No viable dags retrieved from /opt/airflow/dags/xray_test_dag.py
[2023-02-23 01:57:23,910] {processor.py:161} INFO - Processing /opt/airflow/dags/xray_test_dag.py took 0.051 seconds
[2023-02-23 01:57:53,966] {processor.py:153} INFO - Started process (PID=228) to work on /opt/airflow/dags/xray_test_dag.py
[2023-02-23 01:57:53,967] {processor.py:641} INFO - Processing file /opt/airflow/dags/xray_test_dag.py for tasks to queue
[2023-02-23 01:57:53,971] {logging_mixin.py:115} INFO - [2023-02-23 01:57:53,971] {dagbag.py:507} INFO - Filling up the DagBag from /opt/airflow/dags/xray_test_dag.py
[2023-02-23 01:57:53,983] {logging_mixin.py:115} INFO - [2023-02-23 01:57:53,980] {dagbag.py:320} ERROR - Failed to import: /opt/airflow/dags/xray_test_dag.py
Traceback (most recent call last):
  File "/home/airflow/.local/lib/python3.7/site-packages/airflow/models/dagbag.py", line 317, in parse
    loader.exec_module(new_module)
  File "<frozen importlib._bootstrap_external>", line 728, in exec_module
  File "<frozen importlib._bootstrap>", line 219, in _call_with_frames_removed
  File "/opt/airflow/dags/xray_test_dag.py", line 11, in <module>
    catchup=False,
TypeError: __init__() got an unexpected keyword argument 'schedule'
[2023-02-23 01:57:53,984] {processor.py:653} WARNING - No viable dags retrieved from /opt/airflow/dags/xray_test_dag.py
[2023-02-23 01:57:54,001] {processor.py:161} INFO - Processing /opt/airflow/dags/xray_test_dag.py took 0.037 seconds
[2023-02-23 01:58:24,101] {processor.py:153} INFO - Started process (PID=233) to work on /opt/airflow/dags/xray_test_dag.py
[2023-02-23 01:58:24,101] {processor.py:641} INFO - Processing file /opt/airflow/dags/xray_test_dag.py for tasks to queue
[2023-02-23 01:58:24,105] {logging_mixin.py:115} INFO - [2023-02-23 01:58:24,105] {dagbag.py:507} INFO - Filling up the DagBag from /opt/airflow/dags/xray_test_dag.py
[2023-02-23 01:58:24,117] {logging_mixin.py:115} INFO - [2023-02-23 01:58:24,114] {dagbag.py:320} ERROR - Failed to import: /opt/airflow/dags/xray_test_dag.py
Traceback (most recent call last):
  File "/home/airflow/.local/lib/python3.7/site-packages/airflow/models/dagbag.py", line 317, in parse
    loader.exec_module(new_module)
  File "<frozen importlib._bootstrap_external>", line 728, in exec_module
  File "<frozen importlib._bootstrap>", line 219, in _call_with_frames_removed
  File "/opt/airflow/dags/xray_test_dag.py", line 11, in <module>
    catchup=False,
TypeError: __init__() got an unexpected keyword argument 'schedule'
[2023-02-23 01:58:24,118] {processor.py:653} WARNING - No viable dags retrieved from /opt/airflow/dags/xray_test_dag.py
[2023-02-23 01:58:24,146] {processor.py:161} INFO - Processing /opt/airflow/dags/xray_test_dag.py took 0.047 seconds
[2023-02-23 01:58:54,238] {processor.py:153} INFO - Started process (PID=238) to work on /opt/airflow/dags/xray_test_dag.py
[2023-02-23 01:58:54,239] {processor.py:641} INFO - Processing file /opt/airflow/dags/xray_test_dag.py for tasks to queue
[2023-02-23 01:58:54,239] {logging_mixin.py:115} INFO - [2023-02-23 01:58:54,239] {dagbag.py:507} INFO - Filling up the DagBag from /opt/airflow/dags/xray_test_dag.py
[2023-02-23 01:58:54,254] {logging_mixin.py:115} INFO - [2023-02-23 01:58:54,250] {dagbag.py:320} ERROR - Failed to import: /opt/airflow/dags/xray_test_dag.py
Traceback (most recent call last):
  File "/home/airflow/.local/lib/python3.7/site-packages/airflow/models/dagbag.py", line 317, in parse
    loader.exec_module(new_module)
  File "<frozen importlib._bootstrap_external>", line 728, in exec_module
  File "<frozen importlib._bootstrap>", line 219, in _call_with_frames_removed
  File "/opt/airflow/dags/xray_test_dag.py", line 11, in <module>
    catchup=False,
TypeError: __init__() got an unexpected keyword argument 'schedule'
[2023-02-23 01:58:54,255] {processor.py:653} WARNING - No viable dags retrieved from /opt/airflow/dags/xray_test_dag.py
[2023-02-23 01:58:54,279] {processor.py:161} INFO - Processing /opt/airflow/dags/xray_test_dag.py took 0.043 seconds
[2023-02-23 01:59:24,343] {processor.py:153} INFO - Started process (PID=243) to work on /opt/airflow/dags/xray_test_dag.py
[2023-02-23 01:59:24,344] {processor.py:641} INFO - Processing file /opt/airflow/dags/xray_test_dag.py for tasks to queue
[2023-02-23 01:59:24,345] {logging_mixin.py:115} INFO - [2023-02-23 01:59:24,345] {dagbag.py:507} INFO - Filling up the DagBag from /opt/airflow/dags/xray_test_dag.py
[2023-02-23 01:59:24,361] {logging_mixin.py:115} INFO - [2023-02-23 01:59:24,357] {dagbag.py:320} ERROR - Failed to import: /opt/airflow/dags/xray_test_dag.py
Traceback (most recent call last):
  File "/home/airflow/.local/lib/python3.7/site-packages/airflow/models/dagbag.py", line 317, in parse
    loader.exec_module(new_module)
  File "<frozen importlib._bootstrap_external>", line 728, in exec_module
  File "<frozen importlib._bootstrap>", line 219, in _call_with_frames_removed
  File "/opt/airflow/dags/xray_test_dag.py", line 11, in <module>
    catchup=False,
TypeError: __init__() got an unexpected keyword argument 'schedule'
[2023-02-23 01:59:24,363] {processor.py:653} WARNING - No viable dags retrieved from /opt/airflow/dags/xray_test_dag.py
[2023-02-23 01:59:24,394] {processor.py:161} INFO - Processing /opt/airflow/dags/xray_test_dag.py took 0.054 seconds
[2023-02-23 01:59:54,472] {processor.py:153} INFO - Started process (PID=248) to work on /opt/airflow/dags/xray_test_dag.py
[2023-02-23 01:59:54,472] {processor.py:641} INFO - Processing file /opt/airflow/dags/xray_test_dag.py for tasks to queue
[2023-02-23 01:59:54,473] {logging_mixin.py:115} INFO - [2023-02-23 01:59:54,473] {dagbag.py:507} INFO - Filling up the DagBag from /opt/airflow/dags/xray_test_dag.py
[2023-02-23 01:59:54,484] {logging_mixin.py:115} INFO - [2023-02-23 01:59:54,482] {dagbag.py:320} ERROR - Failed to import: /opt/airflow/dags/xray_test_dag.py
Traceback (most recent call last):
  File "/home/airflow/.local/lib/python3.7/site-packages/airflow/models/dagbag.py", line 317, in parse
    loader.exec_module(new_module)
  File "<frozen importlib._bootstrap_external>", line 728, in exec_module
  File "<frozen importlib._bootstrap>", line 219, in _call_with_frames_removed
  File "/opt/airflow/dags/xray_test_dag.py", line 11, in <module>
    catchup=False,
TypeError: __init__() got an unexpected keyword argument 'schedule'
[2023-02-23 01:59:54,485] {processor.py:653} WARNING - No viable dags retrieved from /opt/airflow/dags/xray_test_dag.py
[2023-02-23 01:59:54,514] {processor.py:161} INFO - Processing /opt/airflow/dags/xray_test_dag.py took 0.045 seconds
[2023-02-23 02:00:24,585] {processor.py:153} INFO - Started process (PID=253) to work on /opt/airflow/dags/xray_test_dag.py
[2023-02-23 02:00:24,586] {processor.py:641} INFO - Processing file /opt/airflow/dags/xray_test_dag.py for tasks to queue
[2023-02-23 02:00:24,587] {logging_mixin.py:115} INFO - [2023-02-23 02:00:24,587] {dagbag.py:507} INFO - Filling up the DagBag from /opt/airflow/dags/xray_test_dag.py
[2023-02-23 02:00:24,599] {logging_mixin.py:115} INFO - [2023-02-23 02:00:24,596] {dagbag.py:320} ERROR - Failed to import: /opt/airflow/dags/xray_test_dag.py
Traceback (most recent call last):
  File "/home/airflow/.local/lib/python3.7/site-packages/airflow/models/dagbag.py", line 317, in parse
    loader.exec_module(new_module)
  File "<frozen importlib._bootstrap_external>", line 728, in exec_module
  File "<frozen importlib._bootstrap>", line 219, in _call_with_frames_removed
  File "/opt/airflow/dags/xray_test_dag.py", line 11, in <module>
    catchup=False,
TypeError: __init__() got an unexpected keyword argument 'schedule'
[2023-02-23 02:00:24,600] {processor.py:653} WARNING - No viable dags retrieved from /opt/airflow/dags/xray_test_dag.py
[2023-02-23 02:00:24,617] {processor.py:161} INFO - Processing /opt/airflow/dags/xray_test_dag.py took 0.034 seconds
[2023-02-23 02:00:54,712] {processor.py:153} INFO - Started process (PID=258) to work on /opt/airflow/dags/xray_test_dag.py
[2023-02-23 02:00:54,713] {processor.py:641} INFO - Processing file /opt/airflow/dags/xray_test_dag.py for tasks to queue
[2023-02-23 02:00:54,713] {logging_mixin.py:115} INFO - [2023-02-23 02:00:54,713] {dagbag.py:507} INFO - Filling up the DagBag from /opt/airflow/dags/xray_test_dag.py
[2023-02-23 02:00:54,725] {logging_mixin.py:115} INFO - [2023-02-23 02:00:54,723] {dagbag.py:320} ERROR - Failed to import: /opt/airflow/dags/xray_test_dag.py
Traceback (most recent call last):
  File "/home/airflow/.local/lib/python3.7/site-packages/airflow/models/dagbag.py", line 317, in parse
    loader.exec_module(new_module)
  File "<frozen importlib._bootstrap_external>", line 728, in exec_module
  File "<frozen importlib._bootstrap>", line 219, in _call_with_frames_removed
  File "/opt/airflow/dags/xray_test_dag.py", line 11, in <module>
    catchup=False,
TypeError: __init__() got an unexpected keyword argument 'schedule'
[2023-02-23 02:00:54,726] {processor.py:653} WARNING - No viable dags retrieved from /opt/airflow/dags/xray_test_dag.py
[2023-02-23 02:00:54,747] {processor.py:161} INFO - Processing /opt/airflow/dags/xray_test_dag.py took 0.037 seconds
[2023-02-23 02:01:24,817] {processor.py:153} INFO - Started process (PID=263) to work on /opt/airflow/dags/xray_test_dag.py
[2023-02-23 02:01:24,818] {processor.py:641} INFO - Processing file /opt/airflow/dags/xray_test_dag.py for tasks to queue
[2023-02-23 02:01:24,818] {logging_mixin.py:115} INFO - [2023-02-23 02:01:24,818] {dagbag.py:507} INFO - Filling up the DagBag from /opt/airflow/dags/xray_test_dag.py
[2023-02-23 02:01:24,832] {logging_mixin.py:115} INFO - [2023-02-23 02:01:24,829] {dagbag.py:320} ERROR - Failed to import: /opt/airflow/dags/xray_test_dag.py
Traceback (most recent call last):
  File "/home/airflow/.local/lib/python3.7/site-packages/airflow/models/dagbag.py", line 317, in parse
    loader.exec_module(new_module)
  File "<frozen importlib._bootstrap_external>", line 728, in exec_module
  File "<frozen importlib._bootstrap>", line 219, in _call_with_frames_removed
  File "/opt/airflow/dags/xray_test_dag.py", line 11, in <module>
    catchup=False,
TypeError: __init__() got an unexpected keyword argument 'schedule'
[2023-02-23 02:01:24,833] {processor.py:653} WARNING - No viable dags retrieved from /opt/airflow/dags/xray_test_dag.py
[2023-02-23 02:01:24,984] {processor.py:161} INFO - Processing /opt/airflow/dags/xray_test_dag.py took 0.169 seconds
[2023-02-23 02:01:55,081] {processor.py:153} INFO - Started process (PID=268) to work on /opt/airflow/dags/xray_test_dag.py
[2023-02-23 02:01:55,081] {processor.py:641} INFO - Processing file /opt/airflow/dags/xray_test_dag.py for tasks to queue
[2023-02-23 02:01:55,082] {logging_mixin.py:115} INFO - [2023-02-23 02:01:55,082] {dagbag.py:507} INFO - Filling up the DagBag from /opt/airflow/dags/xray_test_dag.py
[2023-02-23 02:01:55,094] {logging_mixin.py:115} INFO - [2023-02-23 02:01:55,091] {dagbag.py:320} ERROR - Failed to import: /opt/airflow/dags/xray_test_dag.py
Traceback (most recent call last):
  File "/home/airflow/.local/lib/python3.7/site-packages/airflow/models/dagbag.py", line 317, in parse
    loader.exec_module(new_module)
  File "<frozen importlib._bootstrap_external>", line 728, in exec_module
  File "<frozen importlib._bootstrap>", line 219, in _call_with_frames_removed
  File "/opt/airflow/dags/xray_test_dag.py", line 11, in <module>
    catchup=False,
TypeError: __init__() got an unexpected keyword argument 'schedule'
[2023-02-23 02:01:55,094] {processor.py:653} WARNING - No viable dags retrieved from /opt/airflow/dags/xray_test_dag.py
[2023-02-23 02:01:55,125] {processor.py:161} INFO - Processing /opt/airflow/dags/xray_test_dag.py took 0.046 seconds
[2023-02-23 02:02:25,183] {processor.py:153} INFO - Started process (PID=273) to work on /opt/airflow/dags/xray_test_dag.py
[2023-02-23 02:02:25,184] {processor.py:641} INFO - Processing file /opt/airflow/dags/xray_test_dag.py for tasks to queue
[2023-02-23 02:02:25,185] {logging_mixin.py:115} INFO - [2023-02-23 02:02:25,185] {dagbag.py:507} INFO - Filling up the DagBag from /opt/airflow/dags/xray_test_dag.py
[2023-02-23 02:02:25,200] {logging_mixin.py:115} INFO - [2023-02-23 02:02:25,197] {dagbag.py:320} ERROR - Failed to import: /opt/airflow/dags/xray_test_dag.py
Traceback (most recent call last):
  File "/home/airflow/.local/lib/python3.7/site-packages/airflow/models/dagbag.py", line 317, in parse
    loader.exec_module(new_module)
  File "<frozen importlib._bootstrap_external>", line 728, in exec_module
  File "<frozen importlib._bootstrap>", line 219, in _call_with_frames_removed
  File "/opt/airflow/dags/xray_test_dag.py", line 11, in <module>
    catchup=False,
TypeError: __init__() got an unexpected keyword argument 'schedule'
[2023-02-23 02:02:25,202] {processor.py:653} WARNING - No viable dags retrieved from /opt/airflow/dags/xray_test_dag.py
[2023-02-23 02:02:25,233] {processor.py:161} INFO - Processing /opt/airflow/dags/xray_test_dag.py took 0.054 seconds
[2023-02-23 02:02:55,310] {processor.py:153} INFO - Started process (PID=278) to work on /opt/airflow/dags/xray_test_dag.py
[2023-02-23 02:02:55,310] {processor.py:641} INFO - Processing file /opt/airflow/dags/xray_test_dag.py for tasks to queue
[2023-02-23 02:02:55,311] {logging_mixin.py:115} INFO - [2023-02-23 02:02:55,311] {dagbag.py:507} INFO - Filling up the DagBag from /opt/airflow/dags/xray_test_dag.py
[2023-02-23 02:02:55,324] {logging_mixin.py:115} INFO - [2023-02-23 02:02:55,321] {dagbag.py:320} ERROR - Failed to import: /opt/airflow/dags/xray_test_dag.py
Traceback (most recent call last):
  File "/home/airflow/.local/lib/python3.7/site-packages/airflow/models/dagbag.py", line 317, in parse
    loader.exec_module(new_module)
  File "<frozen importlib._bootstrap_external>", line 728, in exec_module
  File "<frozen importlib._bootstrap>", line 219, in _call_with_frames_removed
  File "/opt/airflow/dags/xray_test_dag.py", line 11, in <module>
    catchup=False,
TypeError: __init__() got an unexpected keyword argument 'schedule'
[2023-02-23 02:02:55,325] {processor.py:653} WARNING - No viable dags retrieved from /opt/airflow/dags/xray_test_dag.py
[2023-02-23 02:02:55,357] {processor.py:161} INFO - Processing /opt/airflow/dags/xray_test_dag.py took 0.049 seconds
[2023-02-23 02:03:23,417] {processor.py:153} INFO - Started process (PID=283) to work on /opt/airflow/dags/xray_test_dag.py
[2023-02-23 02:03:23,418] {processor.py:641} INFO - Processing file /opt/airflow/dags/xray_test_dag.py for tasks to queue
[2023-02-23 02:03:23,419] {logging_mixin.py:115} INFO - [2023-02-23 02:03:23,418] {dagbag.py:507} INFO - Filling up the DagBag from /opt/airflow/dags/xray_test_dag.py
[2023-02-23 02:03:23,444] {logging_mixin.py:115} INFO - [2023-02-23 02:03:23,440] {dagbag.py:320} ERROR - Failed to import: /opt/airflow/dags/xray_test_dag.py
Traceback (most recent call last):
  File "/home/airflow/.local/lib/python3.7/site-packages/airflow/models/dagbag.py", line 317, in parse
    loader.exec_module(new_module)
  File "<frozen importlib._bootstrap_external>", line 728, in exec_module
  File "<frozen importlib._bootstrap>", line 219, in _call_with_frames_removed
  File "/opt/airflow/dags/xray_test_dag.py", line 12, in <module>
    catchup=False,
TypeError: __init__() got an unexpected keyword argument 'schedule'
[2023-02-23 02:03:23,445] {processor.py:653} WARNING - No viable dags retrieved from /opt/airflow/dags/xray_test_dag.py
[2023-02-23 02:03:23,463] {processor.py:161} INFO - Processing /opt/airflow/dags/xray_test_dag.py took 0.049 seconds
[2023-02-23 02:03:53,568] {processor.py:153} INFO - Started process (PID=288) to work on /opt/airflow/dags/xray_test_dag.py
[2023-02-23 02:03:53,569] {processor.py:641} INFO - Processing file /opt/airflow/dags/xray_test_dag.py for tasks to queue
[2023-02-23 02:03:53,569] {logging_mixin.py:115} INFO - [2023-02-23 02:03:53,569] {dagbag.py:507} INFO - Filling up the DagBag from /opt/airflow/dags/xray_test_dag.py
[2023-02-23 02:03:53,581] {logging_mixin.py:115} INFO - [2023-02-23 02:03:53,578] {dagbag.py:320} ERROR - Failed to import: /opt/airflow/dags/xray_test_dag.py
Traceback (most recent call last):
  File "/home/airflow/.local/lib/python3.7/site-packages/airflow/models/dagbag.py", line 317, in parse
    loader.exec_module(new_module)
  File "<frozen importlib._bootstrap_external>", line 728, in exec_module
  File "<frozen importlib._bootstrap>", line 219, in _call_with_frames_removed
  File "/opt/airflow/dags/xray_test_dag.py", line 12, in <module>
    catchup=False,
TypeError: __init__() got an unexpected keyword argument 'schedule'
[2023-02-23 02:03:53,582] {processor.py:653} WARNING - No viable dags retrieved from /opt/airflow/dags/xray_test_dag.py
[2023-02-23 02:03:53,599] {processor.py:161} INFO - Processing /opt/airflow/dags/xray_test_dag.py took 0.034 seconds
[2023-02-23 02:04:23,679] {processor.py:153} INFO - Started process (PID=293) to work on /opt/airflow/dags/xray_test_dag.py
[2023-02-23 02:04:23,679] {processor.py:641} INFO - Processing file /opt/airflow/dags/xray_test_dag.py for tasks to queue
[2023-02-23 02:04:23,680] {logging_mixin.py:115} INFO - [2023-02-23 02:04:23,680] {dagbag.py:507} INFO - Filling up the DagBag from /opt/airflow/dags/xray_test_dag.py
[2023-02-23 02:04:23,692] {logging_mixin.py:115} INFO - [2023-02-23 02:04:23,689] {dagbag.py:320} ERROR - Failed to import: /opt/airflow/dags/xray_test_dag.py
Traceback (most recent call last):
  File "/home/airflow/.local/lib/python3.7/site-packages/airflow/models/dagbag.py", line 317, in parse
    loader.exec_module(new_module)
  File "<frozen importlib._bootstrap_external>", line 728, in exec_module
  File "<frozen importlib._bootstrap>", line 219, in _call_with_frames_removed
  File "/opt/airflow/dags/xray_test_dag.py", line 12, in <module>
    catchup=False,
TypeError: __init__() got an unexpected keyword argument 'schedule'
[2023-02-23 02:04:23,692] {processor.py:653} WARNING - No viable dags retrieved from /opt/airflow/dags/xray_test_dag.py
[2023-02-23 02:04:23,722] {processor.py:161} INFO - Processing /opt/airflow/dags/xray_test_dag.py took 0.046 seconds
[2023-02-23 02:04:53,798] {processor.py:153} INFO - Started process (PID=298) to work on /opt/airflow/dags/xray_test_dag.py
[2023-02-23 02:04:53,798] {processor.py:641} INFO - Processing file /opt/airflow/dags/xray_test_dag.py for tasks to queue
[2023-02-23 02:04:53,799] {logging_mixin.py:115} INFO - [2023-02-23 02:04:53,799] {dagbag.py:507} INFO - Filling up the DagBag from /opt/airflow/dags/xray_test_dag.py
[2023-02-23 02:04:53,810] {logging_mixin.py:115} INFO - [2023-02-23 02:04:53,808] {dagbag.py:320} ERROR - Failed to import: /opt/airflow/dags/xray_test_dag.py
Traceback (most recent call last):
  File "/home/airflow/.local/lib/python3.7/site-packages/airflow/models/dagbag.py", line 317, in parse
    loader.exec_module(new_module)
  File "<frozen importlib._bootstrap_external>", line 728, in exec_module
  File "<frozen importlib._bootstrap>", line 219, in _call_with_frames_removed
  File "/opt/airflow/dags/xray_test_dag.py", line 12, in <module>
    catchup=False,
TypeError: __init__() got an unexpected keyword argument 'schedule'
[2023-02-23 02:04:53,811] {processor.py:653} WARNING - No viable dags retrieved from /opt/airflow/dags/xray_test_dag.py
[2023-02-23 02:04:53,829] {processor.py:161} INFO - Processing /opt/airflow/dags/xray_test_dag.py took 0.034 seconds
[2023-02-23 02:05:23,918] {processor.py:153} INFO - Started process (PID=303) to work on /opt/airflow/dags/xray_test_dag.py
[2023-02-23 02:05:23,919] {processor.py:641} INFO - Processing file /opt/airflow/dags/xray_test_dag.py for tasks to queue
[2023-02-23 02:05:23,920] {logging_mixin.py:115} INFO - [2023-02-23 02:05:23,920] {dagbag.py:507} INFO - Filling up the DagBag from /opt/airflow/dags/xray_test_dag.py
[2023-02-23 02:05:23,932] {logging_mixin.py:115} INFO - [2023-02-23 02:05:23,929] {dagbag.py:320} ERROR - Failed to import: /opt/airflow/dags/xray_test_dag.py
Traceback (most recent call last):
  File "/home/airflow/.local/lib/python3.7/site-packages/airflow/models/dagbag.py", line 317, in parse
    loader.exec_module(new_module)
  File "<frozen importlib._bootstrap_external>", line 728, in exec_module
  File "<frozen importlib._bootstrap>", line 219, in _call_with_frames_removed
  File "/opt/airflow/dags/xray_test_dag.py", line 12, in <module>
    catchup=False,
TypeError: __init__() got an unexpected keyword argument 'schedule'
[2023-02-23 02:05:23,932] {processor.py:653} WARNING - No viable dags retrieved from /opt/airflow/dags/xray_test_dag.py
[2023-02-23 02:05:23,951] {processor.py:161} INFO - Processing /opt/airflow/dags/xray_test_dag.py took 0.035 seconds
[2023-02-23 02:05:30,946] {processor.py:153} INFO - Started process (PID=308) to work on /opt/airflow/dags/xray_test_dag.py
[2023-02-23 02:05:30,947] {processor.py:641} INFO - Processing file /opt/airflow/dags/xray_test_dag.py for tasks to queue
[2023-02-23 02:05:30,948] {logging_mixin.py:115} INFO - [2023-02-23 02:05:30,948] {dagbag.py:507} INFO - Filling up the DagBag from /opt/airflow/dags/xray_test_dag.py
[2023-02-23 02:05:30,974] {logging_mixin.py:115} INFO - [2023-02-23 02:05:30,971] {dagbag.py:320} ERROR - Failed to import: /opt/airflow/dags/xray_test_dag.py
Traceback (most recent call last):
  File "/home/airflow/.local/lib/python3.7/site-packages/airflow/models/dagbag.py", line 317, in parse
    loader.exec_module(new_module)
  File "<frozen importlib._bootstrap_external>", line 728, in exec_module
  File "<frozen importlib._bootstrap>", line 219, in _call_with_frames_removed
  File "/opt/airflow/dags/xray_test_dag.py", line 15, in <module>
    catchup=False,
TypeError: __init__() got an unexpected keyword argument 'schedule'
[2023-02-23 02:05:30,975] {processor.py:653} WARNING - No viable dags retrieved from /opt/airflow/dags/xray_test_dag.py
[2023-02-23 02:05:30,993] {processor.py:161} INFO - Processing /opt/airflow/dags/xray_test_dag.py took 0.049 seconds
[2023-02-23 02:06:01,089] {processor.py:153} INFO - Started process (PID=313) to work on /opt/airflow/dags/xray_test_dag.py
[2023-02-23 02:06:01,089] {processor.py:641} INFO - Processing file /opt/airflow/dags/xray_test_dag.py for tasks to queue
[2023-02-23 02:06:01,090] {logging_mixin.py:115} INFO - [2023-02-23 02:06:01,090] {dagbag.py:507} INFO - Filling up the DagBag from /opt/airflow/dags/xray_test_dag.py
[2023-02-23 02:06:01,102] {logging_mixin.py:115} INFO - [2023-02-23 02:06:01,099] {dagbag.py:320} ERROR - Failed to import: /opt/airflow/dags/xray_test_dag.py
Traceback (most recent call last):
  File "/home/airflow/.local/lib/python3.7/site-packages/airflow/models/dagbag.py", line 317, in parse
    loader.exec_module(new_module)
  File "<frozen importlib._bootstrap_external>", line 728, in exec_module
  File "<frozen importlib._bootstrap>", line 219, in _call_with_frames_removed
  File "/opt/airflow/dags/xray_test_dag.py", line 15, in <module>
    catchup=False,
TypeError: __init__() got an unexpected keyword argument 'schedule'
[2023-02-23 02:06:01,103] {processor.py:653} WARNING - No viable dags retrieved from /opt/airflow/dags/xray_test_dag.py
[2023-02-23 02:06:01,122] {processor.py:161} INFO - Processing /opt/airflow/dags/xray_test_dag.py took 0.035 seconds
[2023-02-23 02:06:31,186] {processor.py:153} INFO - Started process (PID=318) to work on /opt/airflow/dags/xray_test_dag.py
[2023-02-23 02:06:31,187] {processor.py:641} INFO - Processing file /opt/airflow/dags/xray_test_dag.py for tasks to queue
[2023-02-23 02:06:31,187] {logging_mixin.py:115} INFO - [2023-02-23 02:06:31,187] {dagbag.py:507} INFO - Filling up the DagBag from /opt/airflow/dags/xray_test_dag.py
[2023-02-23 02:06:31,199] {logging_mixin.py:115} INFO - [2023-02-23 02:06:31,196] {dagbag.py:320} ERROR - Failed to import: /opt/airflow/dags/xray_test_dag.py
Traceback (most recent call last):
  File "/home/airflow/.local/lib/python3.7/site-packages/airflow/models/dagbag.py", line 317, in parse
    loader.exec_module(new_module)
  File "<frozen importlib._bootstrap_external>", line 728, in exec_module
  File "<frozen importlib._bootstrap>", line 219, in _call_with_frames_removed
  File "/opt/airflow/dags/xray_test_dag.py", line 15, in <module>
    catchup=False,
TypeError: __init__() got an unexpected keyword argument 'schedule'
[2023-02-23 02:06:31,199] {processor.py:653} WARNING - No viable dags retrieved from /opt/airflow/dags/xray_test_dag.py
[2023-02-23 02:06:31,218] {processor.py:161} INFO - Processing /opt/airflow/dags/xray_test_dag.py took 0.034 seconds
[2023-02-23 02:06:56,293] {processor.py:153} INFO - Started process (PID=323) to work on /opt/airflow/dags/xray_test_dag.py
[2023-02-23 02:06:56,294] {processor.py:641} INFO - Processing file /opt/airflow/dags/xray_test_dag.py for tasks to queue
[2023-02-23 02:06:56,295] {logging_mixin.py:115} INFO - [2023-02-23 02:06:56,295] {dagbag.py:507} INFO - Filling up the DagBag from /opt/airflow/dags/xray_test_dag.py
[2023-02-23 02:06:56,322] {logging_mixin.py:115} INFO - [2023-02-23 02:06:56,317] {dagbag.py:320} ERROR - Failed to import: /opt/airflow/dags/xray_test_dag.py
Traceback (most recent call last):
  File "/home/airflow/.local/lib/python3.7/site-packages/airflow/models/dagbag.py", line 317, in parse
    loader.exec_module(new_module)
  File "<frozen importlib._bootstrap_external>", line 728, in exec_module
  File "<frozen importlib._bootstrap>", line 219, in _call_with_frames_removed
  File "/opt/airflow/dags/xray_test_dag.py", line 89, in <module>
    task_id= 'unzipped process complete'
  File "/home/airflow/.local/lib/python3.7/site-packages/airflow/models/baseoperator.py", line 390, in apply_defaults
    result = func(self, **kwargs, default_args=default_args)
  File "/home/airflow/.local/lib/python3.7/site-packages/airflow/models/baseoperator.py", line 390, in apply_defaults
    result = func(self, **kwargs, default_args=default_args)
  File "/home/airflow/.local/lib/python3.7/site-packages/airflow/models/baseoperator.py", line 754, in __init__
    validate_key(task_id)
  File "/home/airflow/.local/lib/python3.7/site-packages/airflow/utils/helpers.py", line 64, in validate_key
    f"The key {k!r} has to be made of alphanumeric characters, dashes, "
airflow.exceptions.AirflowException: The key 'unzipped process complete' has to be made of alphanumeric characters, dashes, dots and underscores exclusively
[2023-02-23 02:06:56,322] {processor.py:653} WARNING - No viable dags retrieved from /opt/airflow/dags/xray_test_dag.py
[2023-02-23 02:06:56,342] {processor.py:161} INFO - Processing /opt/airflow/dags/xray_test_dag.py took 0.051 seconds
[2023-02-23 02:07:26,396] {processor.py:153} INFO - Started process (PID=328) to work on /opt/airflow/dags/xray_test_dag.py
[2023-02-23 02:07:26,397] {processor.py:641} INFO - Processing file /opt/airflow/dags/xray_test_dag.py for tasks to queue
[2023-02-23 02:07:26,397] {logging_mixin.py:115} INFO - [2023-02-23 02:07:26,397] {dagbag.py:507} INFO - Filling up the DagBag from /opt/airflow/dags/xray_test_dag.py
[2023-02-23 02:07:26,416] {logging_mixin.py:115} INFO - [2023-02-23 02:07:26,412] {dagbag.py:320} ERROR - Failed to import: /opt/airflow/dags/xray_test_dag.py
Traceback (most recent call last):
  File "/home/airflow/.local/lib/python3.7/site-packages/airflow/models/dagbag.py", line 317, in parse
    loader.exec_module(new_module)
  File "<frozen importlib._bootstrap_external>", line 728, in exec_module
  File "<frozen importlib._bootstrap>", line 219, in _call_with_frames_removed
  File "/opt/airflow/dags/xray_test_dag.py", line 89, in <module>
    task_id= 'unzipped process complete'
  File "/home/airflow/.local/lib/python3.7/site-packages/airflow/models/baseoperator.py", line 390, in apply_defaults
    result = func(self, **kwargs, default_args=default_args)
  File "/home/airflow/.local/lib/python3.7/site-packages/airflow/models/baseoperator.py", line 390, in apply_defaults
    result = func(self, **kwargs, default_args=default_args)
  File "/home/airflow/.local/lib/python3.7/site-packages/airflow/models/baseoperator.py", line 754, in __init__
    validate_key(task_id)
  File "/home/airflow/.local/lib/python3.7/site-packages/airflow/utils/helpers.py", line 64, in validate_key
    f"The key {k!r} has to be made of alphanumeric characters, dashes, "
airflow.exceptions.AirflowException: The key 'unzipped process complete' has to be made of alphanumeric characters, dashes, dots and underscores exclusively
[2023-02-23 02:07:26,417] {processor.py:653} WARNING - No viable dags retrieved from /opt/airflow/dags/xray_test_dag.py
[2023-02-23 02:07:26,446] {processor.py:161} INFO - Processing /opt/airflow/dags/xray_test_dag.py took 0.052 seconds
[2023-02-23 02:07:36,468] {processor.py:153} INFO - Started process (PID=333) to work on /opt/airflow/dags/xray_test_dag.py
[2023-02-23 02:07:36,469] {processor.py:641} INFO - Processing file /opt/airflow/dags/xray_test_dag.py for tasks to queue
[2023-02-23 02:07:36,469] {logging_mixin.py:115} INFO - [2023-02-23 02:07:36,469] {dagbag.py:507} INFO - Filling up the DagBag from /opt/airflow/dags/xray_test_dag.py
[2023-02-23 02:07:36,496] {logging_mixin.py:115} INFO - [2023-02-23 02:07:36,491] {dagbag.py:320} ERROR - Failed to import: /opt/airflow/dags/xray_test_dag.py
Traceback (most recent call last):
  File "/home/airflow/.local/lib/python3.7/site-packages/airflow/models/dagbag.py", line 317, in parse
    loader.exec_module(new_module)
  File "<frozen importlib._bootstrap_external>", line 728, in exec_module
  File "<frozen importlib._bootstrap>", line 219, in _call_with_frames_removed
  File "/opt/airflow/dags/xray_test_dag.py", line 89, in <module>
    task_id= 'unzipped process complete'
  File "/home/airflow/.local/lib/python3.7/site-packages/airflow/models/baseoperator.py", line 390, in apply_defaults
    result = func(self, **kwargs, default_args=default_args)
  File "/home/airflow/.local/lib/python3.7/site-packages/airflow/models/baseoperator.py", line 390, in apply_defaults
    result = func(self, **kwargs, default_args=default_args)
  File "/home/airflow/.local/lib/python3.7/site-packages/airflow/models/baseoperator.py", line 754, in __init__
    validate_key(task_id)
  File "/home/airflow/.local/lib/python3.7/site-packages/airflow/utils/helpers.py", line 64, in validate_key
    f"The key {k!r} has to be made of alphanumeric characters, dashes, "
airflow.exceptions.AirflowException: The key 'unzipped process complete' has to be made of alphanumeric characters, dashes, dots and underscores exclusively
[2023-02-23 02:07:36,496] {processor.py:653} WARNING - No viable dags retrieved from /opt/airflow/dags/xray_test_dag.py
[2023-02-23 02:07:36,513] {processor.py:161} INFO - Processing /opt/airflow/dags/xray_test_dag.py took 0.048 seconds
[2023-02-23 02:08:06,599] {processor.py:153} INFO - Started process (PID=338) to work on /opt/airflow/dags/xray_test_dag.py
[2023-02-23 02:08:06,599] {processor.py:641} INFO - Processing file /opt/airflow/dags/xray_test_dag.py for tasks to queue
[2023-02-23 02:08:06,600] {logging_mixin.py:115} INFO - [2023-02-23 02:08:06,600] {dagbag.py:507} INFO - Filling up the DagBag from /opt/airflow/dags/xray_test_dag.py
[2023-02-23 02:08:06,618] {logging_mixin.py:115} INFO - [2023-02-23 02:08:06,614] {dagbag.py:320} ERROR - Failed to import: /opt/airflow/dags/xray_test_dag.py
Traceback (most recent call last):
  File "/home/airflow/.local/lib/python3.7/site-packages/airflow/models/dagbag.py", line 317, in parse
    loader.exec_module(new_module)
  File "<frozen importlib._bootstrap_external>", line 728, in exec_module
  File "<frozen importlib._bootstrap>", line 219, in _call_with_frames_removed
  File "/opt/airflow/dags/xray_test_dag.py", line 89, in <module>
    task_id= 'unzipped process complete'
  File "/home/airflow/.local/lib/python3.7/site-packages/airflow/models/baseoperator.py", line 390, in apply_defaults
    result = func(self, **kwargs, default_args=default_args)
  File "/home/airflow/.local/lib/python3.7/site-packages/airflow/models/baseoperator.py", line 390, in apply_defaults
    result = func(self, **kwargs, default_args=default_args)
  File "/home/airflow/.local/lib/python3.7/site-packages/airflow/models/baseoperator.py", line 754, in __init__
    validate_key(task_id)
  File "/home/airflow/.local/lib/python3.7/site-packages/airflow/utils/helpers.py", line 64, in validate_key
    f"The key {k!r} has to be made of alphanumeric characters, dashes, "
airflow.exceptions.AirflowException: The key 'unzipped process complete' has to be made of alphanumeric characters, dashes, dots and underscores exclusively
[2023-02-23 02:08:06,618] {processor.py:653} WARNING - No viable dags retrieved from /opt/airflow/dags/xray_test_dag.py
[2023-02-23 02:08:06,636] {processor.py:161} INFO - Processing /opt/airflow/dags/xray_test_dag.py took 0.039 seconds
[2023-02-23 02:08:36,711] {processor.py:153} INFO - Started process (PID=343) to work on /opt/airflow/dags/xray_test_dag.py
[2023-02-23 02:08:36,712] {processor.py:641} INFO - Processing file /opt/airflow/dags/xray_test_dag.py for tasks to queue
[2023-02-23 02:08:36,713] {logging_mixin.py:115} INFO - [2023-02-23 02:08:36,712] {dagbag.py:507} INFO - Filling up the DagBag from /opt/airflow/dags/xray_test_dag.py
[2023-02-23 02:08:36,732] {logging_mixin.py:115} INFO - [2023-02-23 02:08:36,727] {dagbag.py:320} ERROR - Failed to import: /opt/airflow/dags/xray_test_dag.py
Traceback (most recent call last):
  File "/home/airflow/.local/lib/python3.7/site-packages/airflow/models/dagbag.py", line 317, in parse
    loader.exec_module(new_module)
  File "<frozen importlib._bootstrap_external>", line 728, in exec_module
  File "<frozen importlib._bootstrap>", line 219, in _call_with_frames_removed
  File "/opt/airflow/dags/xray_test_dag.py", line 89, in <module>
    task_id= 'unzipped process complete'
  File "/home/airflow/.local/lib/python3.7/site-packages/airflow/models/baseoperator.py", line 390, in apply_defaults
    result = func(self, **kwargs, default_args=default_args)
  File "/home/airflow/.local/lib/python3.7/site-packages/airflow/models/baseoperator.py", line 390, in apply_defaults
    result = func(self, **kwargs, default_args=default_args)
  File "/home/airflow/.local/lib/python3.7/site-packages/airflow/models/baseoperator.py", line 754, in __init__
    validate_key(task_id)
  File "/home/airflow/.local/lib/python3.7/site-packages/airflow/utils/helpers.py", line 64, in validate_key
    f"The key {k!r} has to be made of alphanumeric characters, dashes, "
airflow.exceptions.AirflowException: The key 'unzipped process complete' has to be made of alphanumeric characters, dashes, dots and underscores exclusively
[2023-02-23 02:08:36,732] {processor.py:653} WARNING - No viable dags retrieved from /opt/airflow/dags/xray_test_dag.py
[2023-02-23 02:08:36,751] {processor.py:161} INFO - Processing /opt/airflow/dags/xray_test_dag.py took 0.042 seconds
[2023-02-23 02:08:48,774] {processor.py:153} INFO - Started process (PID=348) to work on /opt/airflow/dags/xray_test_dag.py
[2023-02-23 02:08:48,774] {processor.py:641} INFO - Processing file /opt/airflow/dags/xray_test_dag.py for tasks to queue
[2023-02-23 02:08:48,775] {logging_mixin.py:115} INFO - [2023-02-23 02:08:48,775] {dagbag.py:507} INFO - Filling up the DagBag from /opt/airflow/dags/xray_test_dag.py
[2023-02-23 02:08:48,801] {logging_mixin.py:115} INFO - [2023-02-23 02:08:48,797] {dagbag.py:320} ERROR - Failed to import: /opt/airflow/dags/xray_test_dag.py
Traceback (most recent call last):
  File "/home/airflow/.local/lib/python3.7/site-packages/airflow/models/dagbag.py", line 317, in parse
    loader.exec_module(new_module)
  File "<frozen importlib._bootstrap_external>", line 728, in exec_module
  File "<frozen importlib._bootstrap>", line 219, in _call_with_frames_removed
  File "/opt/airflow/dags/xray_test_dag.py", line 89, in <module>
    task_id= 'unzipped process complete'
  File "/home/airflow/.local/lib/python3.7/site-packages/airflow/models/baseoperator.py", line 390, in apply_defaults
    result = func(self, **kwargs, default_args=default_args)
  File "/home/airflow/.local/lib/python3.7/site-packages/airflow/models/baseoperator.py", line 390, in apply_defaults
    result = func(self, **kwargs, default_args=default_args)
  File "/home/airflow/.local/lib/python3.7/site-packages/airflow/models/baseoperator.py", line 754, in __init__
    validate_key(task_id)
  File "/home/airflow/.local/lib/python3.7/site-packages/airflow/utils/helpers.py", line 64, in validate_key
    f"The key {k!r} has to be made of alphanumeric characters, dashes, "
airflow.exceptions.AirflowException: The key 'unzipped process complete' has to be made of alphanumeric characters, dashes, dots and underscores exclusively
[2023-02-23 02:08:48,801] {processor.py:653} WARNING - No viable dags retrieved from /opt/airflow/dags/xray_test_dag.py
[2023-02-23 02:08:48,822] {processor.py:161} INFO - Processing /opt/airflow/dags/xray_test_dag.py took 0.051 seconds
[2023-02-23 02:09:18,922] {processor.py:153} INFO - Started process (PID=353) to work on /opt/airflow/dags/xray_test_dag.py
[2023-02-23 02:09:18,923] {processor.py:641} INFO - Processing file /opt/airflow/dags/xray_test_dag.py for tasks to queue
[2023-02-23 02:09:18,924] {logging_mixin.py:115} INFO - [2023-02-23 02:09:18,923] {dagbag.py:507} INFO - Filling up the DagBag from /opt/airflow/dags/xray_test_dag.py
[2023-02-23 02:09:18,943] {logging_mixin.py:115} INFO - [2023-02-23 02:09:18,938] {dagbag.py:320} ERROR - Failed to import: /opt/airflow/dags/xray_test_dag.py
Traceback (most recent call last):
  File "/home/airflow/.local/lib/python3.7/site-packages/airflow/models/dagbag.py", line 317, in parse
    loader.exec_module(new_module)
  File "<frozen importlib._bootstrap_external>", line 728, in exec_module
  File "<frozen importlib._bootstrap>", line 219, in _call_with_frames_removed
  File "/opt/airflow/dags/xray_test_dag.py", line 89, in <module>
    task_id= 'unzipped process complete'
  File "/home/airflow/.local/lib/python3.7/site-packages/airflow/models/baseoperator.py", line 390, in apply_defaults
    result = func(self, **kwargs, default_args=default_args)
  File "/home/airflow/.local/lib/python3.7/site-packages/airflow/models/baseoperator.py", line 390, in apply_defaults
    result = func(self, **kwargs, default_args=default_args)
  File "/home/airflow/.local/lib/python3.7/site-packages/airflow/models/baseoperator.py", line 754, in __init__
    validate_key(task_id)
  File "/home/airflow/.local/lib/python3.7/site-packages/airflow/utils/helpers.py", line 64, in validate_key
    f"The key {k!r} has to be made of alphanumeric characters, dashes, "
airflow.exceptions.AirflowException: The key 'unzipped process complete' has to be made of alphanumeric characters, dashes, dots and underscores exclusively
[2023-02-23 02:09:18,943] {processor.py:653} WARNING - No viable dags retrieved from /opt/airflow/dags/xray_test_dag.py
[2023-02-23 02:09:18,960] {processor.py:161} INFO - Processing /opt/airflow/dags/xray_test_dag.py took 0.040 seconds
[2023-02-23 02:09:21,938] {processor.py:153} INFO - Started process (PID=358) to work on /opt/airflow/dags/xray_test_dag.py
[2023-02-23 02:09:21,939] {processor.py:641} INFO - Processing file /opt/airflow/dags/xray_test_dag.py for tasks to queue
[2023-02-23 02:09:21,940] {logging_mixin.py:115} INFO - [2023-02-23 02:09:21,940] {dagbag.py:507} INFO - Filling up the DagBag from /opt/airflow/dags/xray_test_dag.py
[2023-02-23 02:09:21,970] {logging_mixin.py:115} INFO - [2023-02-23 02:09:21,969] {dagbag.py:412} ERROR - Failed to bag_dag: /opt/airflow/dags/xray_test_dag.py
Traceback (most recent call last):
  File "/home/airflow/.local/lib/python3.7/site-packages/croniter/croniter.py", line 172, in _alphaconv
    return cls.ALPHACONV[index][key]
KeyError: '?'

During handling of the above exception, another exception occurred:

Traceback (most recent call last):
  File "/home/airflow/.local/lib/python3.7/site-packages/airflow/timetables/interval.py", line 173, in validate
    croniter(self._expression)
  File "/home/airflow/.local/lib/python3.7/site-packages/croniter/croniter.py", line 166, in __init__
    self.expanded, self.nth_weekday_of_month = self.expand(expr_format, hash_id=hash_id)
  File "/home/airflow/.local/lib/python3.7/site-packages/croniter/croniter.py", line 774, in expand
    return cls._expand(expr_format, hash_id=hash_id)
  File "/home/airflow/.local/lib/python3.7/site-packages/croniter/croniter.py", line 717, in _expand
    t = cls._alphaconv(i, t, expressions)
  File "/home/airflow/.local/lib/python3.7/site-packages/croniter/croniter.py", line 175, in _alphaconv
    "[{0}] is not acceptable".format(" ".join(expressions)))
croniter.croniter.CroniterNotAlphaError: [0 0 4 ? * mon] is not acceptable

During handling of the above exception, another exception occurred:

Traceback (most recent call last):
  File "/home/airflow/.local/lib/python3.7/site-packages/airflow/models/dagbag.py", line 405, in _process_modules
    dag.timetable.validate()
  File "/home/airflow/.local/lib/python3.7/site-packages/airflow/timetables/interval.py", line 175, in validate
    raise AirflowTimetableInvalid(str(e))
airflow.exceptions.AirflowTimetableInvalid: [0 0 4 ? * mon] is not acceptable
[2023-02-23 02:09:21,970] {processor.py:653} WARNING - No viable dags retrieved from /opt/airflow/dags/xray_test_dag.py
[2023-02-23 02:09:21,993] {processor.py:161} INFO - Processing /opt/airflow/dags/xray_test_dag.py took 0.058 seconds
[2023-02-23 02:09:52,085] {processor.py:153} INFO - Started process (PID=363) to work on /opt/airflow/dags/xray_test_dag.py
[2023-02-23 02:09:52,085] {processor.py:641} INFO - Processing file /opt/airflow/dags/xray_test_dag.py for tasks to queue
[2023-02-23 02:09:52,086] {logging_mixin.py:115} INFO - [2023-02-23 02:09:52,086] {dagbag.py:507} INFO - Filling up the DagBag from /opt/airflow/dags/xray_test_dag.py
[2023-02-23 02:09:52,104] {logging_mixin.py:115} INFO - [2023-02-23 02:09:52,103] {dagbag.py:412} ERROR - Failed to bag_dag: /opt/airflow/dags/xray_test_dag.py
Traceback (most recent call last):
  File "/home/airflow/.local/lib/python3.7/site-packages/croniter/croniter.py", line 172, in _alphaconv
    return cls.ALPHACONV[index][key]
KeyError: '?'

During handling of the above exception, another exception occurred:

Traceback (most recent call last):
  File "/home/airflow/.local/lib/python3.7/site-packages/airflow/timetables/interval.py", line 173, in validate
    croniter(self._expression)
  File "/home/airflow/.local/lib/python3.7/site-packages/croniter/croniter.py", line 166, in __init__
    self.expanded, self.nth_weekday_of_month = self.expand(expr_format, hash_id=hash_id)
  File "/home/airflow/.local/lib/python3.7/site-packages/croniter/croniter.py", line 774, in expand
    return cls._expand(expr_format, hash_id=hash_id)
  File "/home/airflow/.local/lib/python3.7/site-packages/croniter/croniter.py", line 717, in _expand
    t = cls._alphaconv(i, t, expressions)
  File "/home/airflow/.local/lib/python3.7/site-packages/croniter/croniter.py", line 175, in _alphaconv
    "[{0}] is not acceptable".format(" ".join(expressions)))
croniter.croniter.CroniterNotAlphaError: [0 0 4 ? * mon] is not acceptable

During handling of the above exception, another exception occurred:

Traceback (most recent call last):
  File "/home/airflow/.local/lib/python3.7/site-packages/airflow/models/dagbag.py", line 405, in _process_modules
    dag.timetable.validate()
  File "/home/airflow/.local/lib/python3.7/site-packages/airflow/timetables/interval.py", line 175, in validate
    raise AirflowTimetableInvalid(str(e))
airflow.exceptions.AirflowTimetableInvalid: [0 0 4 ? * mon] is not acceptable
[2023-02-23 02:09:52,104] {processor.py:653} WARNING - No viable dags retrieved from /opt/airflow/dags/xray_test_dag.py
[2023-02-23 02:09:52,126] {processor.py:161} INFO - Processing /opt/airflow/dags/xray_test_dag.py took 0.044 seconds
[2023-02-23 02:10:22,190] {processor.py:153} INFO - Started process (PID=368) to work on /opt/airflow/dags/xray_test_dag.py
[2023-02-23 02:10:22,190] {processor.py:641} INFO - Processing file /opt/airflow/dags/xray_test_dag.py for tasks to queue
[2023-02-23 02:10:22,191] {logging_mixin.py:115} INFO - [2023-02-23 02:10:22,191] {dagbag.py:507} INFO - Filling up the DagBag from /opt/airflow/dags/xray_test_dag.py
[2023-02-23 02:10:22,208] {logging_mixin.py:115} INFO - [2023-02-23 02:10:22,207] {dagbag.py:412} ERROR - Failed to bag_dag: /opt/airflow/dags/xray_test_dag.py
Traceback (most recent call last):
  File "/home/airflow/.local/lib/python3.7/site-packages/croniter/croniter.py", line 172, in _alphaconv
    return cls.ALPHACONV[index][key]
KeyError: '?'

During handling of the above exception, another exception occurred:

Traceback (most recent call last):
  File "/home/airflow/.local/lib/python3.7/site-packages/airflow/timetables/interval.py", line 173, in validate
    croniter(self._expression)
  File "/home/airflow/.local/lib/python3.7/site-packages/croniter/croniter.py", line 166, in __init__
    self.expanded, self.nth_weekday_of_month = self.expand(expr_format, hash_id=hash_id)
  File "/home/airflow/.local/lib/python3.7/site-packages/croniter/croniter.py", line 774, in expand
    return cls._expand(expr_format, hash_id=hash_id)
  File "/home/airflow/.local/lib/python3.7/site-packages/croniter/croniter.py", line 717, in _expand
    t = cls._alphaconv(i, t, expressions)
  File "/home/airflow/.local/lib/python3.7/site-packages/croniter/croniter.py", line 175, in _alphaconv
    "[{0}] is not acceptable".format(" ".join(expressions)))
croniter.croniter.CroniterNotAlphaError: [0 0 4 ? * mon] is not acceptable

During handling of the above exception, another exception occurred:

Traceback (most recent call last):
  File "/home/airflow/.local/lib/python3.7/site-packages/airflow/models/dagbag.py", line 405, in _process_modules
    dag.timetable.validate()
  File "/home/airflow/.local/lib/python3.7/site-packages/airflow/timetables/interval.py", line 175, in validate
    raise AirflowTimetableInvalid(str(e))
airflow.exceptions.AirflowTimetableInvalid: [0 0 4 ? * mon] is not acceptable
[2023-02-23 02:10:22,208] {processor.py:653} WARNING - No viable dags retrieved from /opt/airflow/dags/xray_test_dag.py
[2023-02-23 02:10:22,225] {processor.py:161} INFO - Processing /opt/airflow/dags/xray_test_dag.py took 0.038 seconds
[2023-02-23 02:10:52,316] {processor.py:153} INFO - Started process (PID=373) to work on /opt/airflow/dags/xray_test_dag.py
[2023-02-23 02:10:52,317] {processor.py:641} INFO - Processing file /opt/airflow/dags/xray_test_dag.py for tasks to queue
[2023-02-23 02:10:52,317] {logging_mixin.py:115} INFO - [2023-02-23 02:10:52,317] {dagbag.py:507} INFO - Filling up the DagBag from /opt/airflow/dags/xray_test_dag.py
[2023-02-23 02:10:52,334] {logging_mixin.py:115} INFO - [2023-02-23 02:10:52,334] {dagbag.py:412} ERROR - Failed to bag_dag: /opt/airflow/dags/xray_test_dag.py
Traceback (most recent call last):
  File "/home/airflow/.local/lib/python3.7/site-packages/croniter/croniter.py", line 172, in _alphaconv
    return cls.ALPHACONV[index][key]
KeyError: '?'

During handling of the above exception, another exception occurred:

Traceback (most recent call last):
  File "/home/airflow/.local/lib/python3.7/site-packages/airflow/timetables/interval.py", line 173, in validate
    croniter(self._expression)
  File "/home/airflow/.local/lib/python3.7/site-packages/croniter/croniter.py", line 166, in __init__
    self.expanded, self.nth_weekday_of_month = self.expand(expr_format, hash_id=hash_id)
  File "/home/airflow/.local/lib/python3.7/site-packages/croniter/croniter.py", line 774, in expand
    return cls._expand(expr_format, hash_id=hash_id)
  File "/home/airflow/.local/lib/python3.7/site-packages/croniter/croniter.py", line 717, in _expand
    t = cls._alphaconv(i, t, expressions)
  File "/home/airflow/.local/lib/python3.7/site-packages/croniter/croniter.py", line 175, in _alphaconv
    "[{0}] is not acceptable".format(" ".join(expressions)))
croniter.croniter.CroniterNotAlphaError: [0 0 4 ? * mon] is not acceptable

During handling of the above exception, another exception occurred:

Traceback (most recent call last):
  File "/home/airflow/.local/lib/python3.7/site-packages/airflow/models/dagbag.py", line 405, in _process_modules
    dag.timetable.validate()
  File "/home/airflow/.local/lib/python3.7/site-packages/airflow/timetables/interval.py", line 175, in validate
    raise AirflowTimetableInvalid(str(e))
airflow.exceptions.AirflowTimetableInvalid: [0 0 4 ? * mon] is not acceptable
[2023-02-23 02:10:52,335] {processor.py:653} WARNING - No viable dags retrieved from /opt/airflow/dags/xray_test_dag.py
[2023-02-23 02:10:52,366] {processor.py:161} INFO - Processing /opt/airflow/dags/xray_test_dag.py took 0.052 seconds
[2023-02-23 02:11:22,425] {processor.py:153} INFO - Started process (PID=378) to work on /opt/airflow/dags/xray_test_dag.py
[2023-02-23 02:11:22,426] {processor.py:641} INFO - Processing file /opt/airflow/dags/xray_test_dag.py for tasks to queue
[2023-02-23 02:11:22,427] {logging_mixin.py:115} INFO - [2023-02-23 02:11:22,427] {dagbag.py:507} INFO - Filling up the DagBag from /opt/airflow/dags/xray_test_dag.py
[2023-02-23 02:11:22,443] {logging_mixin.py:115} INFO - [2023-02-23 02:11:22,442] {dagbag.py:412} ERROR - Failed to bag_dag: /opt/airflow/dags/xray_test_dag.py
Traceback (most recent call last):
  File "/home/airflow/.local/lib/python3.7/site-packages/croniter/croniter.py", line 172, in _alphaconv
    return cls.ALPHACONV[index][key]
KeyError: '?'

During handling of the above exception, another exception occurred:

Traceback (most recent call last):
  File "/home/airflow/.local/lib/python3.7/site-packages/airflow/timetables/interval.py", line 173, in validate
    croniter(self._expression)
  File "/home/airflow/.local/lib/python3.7/site-packages/croniter/croniter.py", line 166, in __init__
    self.expanded, self.nth_weekday_of_month = self.expand(expr_format, hash_id=hash_id)
  File "/home/airflow/.local/lib/python3.7/site-packages/croniter/croniter.py", line 774, in expand
    return cls._expand(expr_format, hash_id=hash_id)
  File "/home/airflow/.local/lib/python3.7/site-packages/croniter/croniter.py", line 717, in _expand
    t = cls._alphaconv(i, t, expressions)
  File "/home/airflow/.local/lib/python3.7/site-packages/croniter/croniter.py", line 175, in _alphaconv
    "[{0}] is not acceptable".format(" ".join(expressions)))
croniter.croniter.CroniterNotAlphaError: [0 0 4 ? * mon] is not acceptable

During handling of the above exception, another exception occurred:

Traceback (most recent call last):
  File "/home/airflow/.local/lib/python3.7/site-packages/airflow/models/dagbag.py", line 405, in _process_modules
    dag.timetable.validate()
  File "/home/airflow/.local/lib/python3.7/site-packages/airflow/timetables/interval.py", line 175, in validate
    raise AirflowTimetableInvalid(str(e))
airflow.exceptions.AirflowTimetableInvalid: [0 0 4 ? * mon] is not acceptable
[2023-02-23 02:11:22,443] {processor.py:653} WARNING - No viable dags retrieved from /opt/airflow/dags/xray_test_dag.py
[2023-02-23 02:11:22,473] {processor.py:161} INFO - Processing /opt/airflow/dags/xray_test_dag.py took 0.051 seconds
[2023-02-23 02:11:52,558] {processor.py:153} INFO - Started process (PID=383) to work on /opt/airflow/dags/xray_test_dag.py
[2023-02-23 02:11:52,559] {processor.py:641} INFO - Processing file /opt/airflow/dags/xray_test_dag.py for tasks to queue
[2023-02-23 02:11:52,559] {logging_mixin.py:115} INFO - [2023-02-23 02:11:52,559] {dagbag.py:507} INFO - Filling up the DagBag from /opt/airflow/dags/xray_test_dag.py
[2023-02-23 02:11:52,575] {logging_mixin.py:115} INFO - [2023-02-23 02:11:52,574] {dagbag.py:412} ERROR - Failed to bag_dag: /opt/airflow/dags/xray_test_dag.py
Traceback (most recent call last):
  File "/home/airflow/.local/lib/python3.7/site-packages/croniter/croniter.py", line 172, in _alphaconv
    return cls.ALPHACONV[index][key]
KeyError: '?'

During handling of the above exception, another exception occurred:

Traceback (most recent call last):
  File "/home/airflow/.local/lib/python3.7/site-packages/airflow/timetables/interval.py", line 173, in validate
    croniter(self._expression)
  File "/home/airflow/.local/lib/python3.7/site-packages/croniter/croniter.py", line 166, in __init__
    self.expanded, self.nth_weekday_of_month = self.expand(expr_format, hash_id=hash_id)
  File "/home/airflow/.local/lib/python3.7/site-packages/croniter/croniter.py", line 774, in expand
    return cls._expand(expr_format, hash_id=hash_id)
  File "/home/airflow/.local/lib/python3.7/site-packages/croniter/croniter.py", line 717, in _expand
    t = cls._alphaconv(i, t, expressions)
  File "/home/airflow/.local/lib/python3.7/site-packages/croniter/croniter.py", line 175, in _alphaconv
    "[{0}] is not acceptable".format(" ".join(expressions)))
croniter.croniter.CroniterNotAlphaError: [0 0 4 ? * mon] is not acceptable

During handling of the above exception, another exception occurred:

Traceback (most recent call last):
  File "/home/airflow/.local/lib/python3.7/site-packages/airflow/models/dagbag.py", line 405, in _process_modules
    dag.timetable.validate()
  File "/home/airflow/.local/lib/python3.7/site-packages/airflow/timetables/interval.py", line 175, in validate
    raise AirflowTimetableInvalid(str(e))
airflow.exceptions.AirflowTimetableInvalid: [0 0 4 ? * mon] is not acceptable
[2023-02-23 02:11:52,576] {processor.py:653} WARNING - No viable dags retrieved from /opt/airflow/dags/xray_test_dag.py
[2023-02-23 02:11:52,607] {processor.py:161} INFO - Processing /opt/airflow/dags/xray_test_dag.py took 0.051 seconds
[2023-02-23 02:12:22,667] {processor.py:153} INFO - Started process (PID=388) to work on /opt/airflow/dags/xray_test_dag.py
[2023-02-23 02:12:22,668] {processor.py:641} INFO - Processing file /opt/airflow/dags/xray_test_dag.py for tasks to queue
[2023-02-23 02:12:22,669] {logging_mixin.py:115} INFO - [2023-02-23 02:12:22,669] {dagbag.py:507} INFO - Filling up the DagBag from /opt/airflow/dags/xray_test_dag.py
[2023-02-23 02:12:22,686] {logging_mixin.py:115} INFO - [2023-02-23 02:12:22,685] {dagbag.py:412} ERROR - Failed to bag_dag: /opt/airflow/dags/xray_test_dag.py
Traceback (most recent call last):
  File "/home/airflow/.local/lib/python3.7/site-packages/croniter/croniter.py", line 172, in _alphaconv
    return cls.ALPHACONV[index][key]
KeyError: '?'

During handling of the above exception, another exception occurred:

Traceback (most recent call last):
  File "/home/airflow/.local/lib/python3.7/site-packages/airflow/timetables/interval.py", line 173, in validate
    croniter(self._expression)
  File "/home/airflow/.local/lib/python3.7/site-packages/croniter/croniter.py", line 166, in __init__
    self.expanded, self.nth_weekday_of_month = self.expand(expr_format, hash_id=hash_id)
  File "/home/airflow/.local/lib/python3.7/site-packages/croniter/croniter.py", line 774, in expand
    return cls._expand(expr_format, hash_id=hash_id)
  File "/home/airflow/.local/lib/python3.7/site-packages/croniter/croniter.py", line 717, in _expand
    t = cls._alphaconv(i, t, expressions)
  File "/home/airflow/.local/lib/python3.7/site-packages/croniter/croniter.py", line 175, in _alphaconv
    "[{0}] is not acceptable".format(" ".join(expressions)))
croniter.croniter.CroniterNotAlphaError: [0 0 4 ? * mon] is not acceptable

During handling of the above exception, another exception occurred:

Traceback (most recent call last):
  File "/home/airflow/.local/lib/python3.7/site-packages/airflow/models/dagbag.py", line 405, in _process_modules
    dag.timetable.validate()
  File "/home/airflow/.local/lib/python3.7/site-packages/airflow/timetables/interval.py", line 175, in validate
    raise AirflowTimetableInvalid(str(e))
airflow.exceptions.AirflowTimetableInvalid: [0 0 4 ? * mon] is not acceptable
[2023-02-23 02:12:22,686] {processor.py:653} WARNING - No viable dags retrieved from /opt/airflow/dags/xray_test_dag.py
[2023-02-23 02:12:22,706] {processor.py:161} INFO - Processing /opt/airflow/dags/xray_test_dag.py took 0.041 seconds
[2023-02-23 02:12:52,798] {processor.py:153} INFO - Started process (PID=393) to work on /opt/airflow/dags/xray_test_dag.py
[2023-02-23 02:12:52,799] {processor.py:641} INFO - Processing file /opt/airflow/dags/xray_test_dag.py for tasks to queue
[2023-02-23 02:12:52,799] {logging_mixin.py:115} INFO - [2023-02-23 02:12:52,799] {dagbag.py:507} INFO - Filling up the DagBag from /opt/airflow/dags/xray_test_dag.py
[2023-02-23 02:12:52,815] {logging_mixin.py:115} INFO - [2023-02-23 02:12:52,814] {dagbag.py:412} ERROR - Failed to bag_dag: /opt/airflow/dags/xray_test_dag.py
Traceback (most recent call last):
  File "/home/airflow/.local/lib/python3.7/site-packages/croniter/croniter.py", line 172, in _alphaconv
    return cls.ALPHACONV[index][key]
KeyError: '?'

During handling of the above exception, another exception occurred:

Traceback (most recent call last):
  File "/home/airflow/.local/lib/python3.7/site-packages/airflow/timetables/interval.py", line 173, in validate
    croniter(self._expression)
  File "/home/airflow/.local/lib/python3.7/site-packages/croniter/croniter.py", line 166, in __init__
    self.expanded, self.nth_weekday_of_month = self.expand(expr_format, hash_id=hash_id)
  File "/home/airflow/.local/lib/python3.7/site-packages/croniter/croniter.py", line 774, in expand
    return cls._expand(expr_format, hash_id=hash_id)
  File "/home/airflow/.local/lib/python3.7/site-packages/croniter/croniter.py", line 717, in _expand
    t = cls._alphaconv(i, t, expressions)
  File "/home/airflow/.local/lib/python3.7/site-packages/croniter/croniter.py", line 175, in _alphaconv
    "[{0}] is not acceptable".format(" ".join(expressions)))
croniter.croniter.CroniterNotAlphaError: [0 0 4 ? * mon] is not acceptable

During handling of the above exception, another exception occurred:

Traceback (most recent call last):
  File "/home/airflow/.local/lib/python3.7/site-packages/airflow/models/dagbag.py", line 405, in _process_modules
    dag.timetable.validate()
  File "/home/airflow/.local/lib/python3.7/site-packages/airflow/timetables/interval.py", line 175, in validate
    raise AirflowTimetableInvalid(str(e))
airflow.exceptions.AirflowTimetableInvalid: [0 0 4 ? * mon] is not acceptable
[2023-02-23 02:12:52,815] {processor.py:653} WARNING - No viable dags retrieved from /opt/airflow/dags/xray_test_dag.py
[2023-02-23 02:12:52,834] {processor.py:161} INFO - Processing /opt/airflow/dags/xray_test_dag.py took 0.038 seconds
[2023-02-23 02:13:09,862] {processor.py:153} INFO - Started process (PID=398) to work on /opt/airflow/dags/xray_test_dag.py
[2023-02-23 02:13:09,862] {processor.py:641} INFO - Processing file /opt/airflow/dags/xray_test_dag.py for tasks to queue
[2023-02-23 02:13:09,863] {logging_mixin.py:115} INFO - [2023-02-23 02:13:09,863] {dagbag.py:507} INFO - Filling up the DagBag from /opt/airflow/dags/xray_test_dag.py
[2023-02-23 02:13:09,886] {logging_mixin.py:115} INFO - [2023-02-23 02:13:09,885] {dagbag.py:412} ERROR - Failed to bag_dag: /opt/airflow/dags/xray_test_dag.py
Traceback (most recent call last):
  File "/home/airflow/.local/lib/python3.7/site-packages/airflow/timetables/interval.py", line 173, in validate
    croniter(self._expression)
  File "/home/airflow/.local/lib/python3.7/site-packages/croniter/croniter.py", line 166, in __init__
    self.expanded, self.nth_weekday_of_month = self.expand(expr_format, hash_id=hash_id)
  File "/home/airflow/.local/lib/python3.7/site-packages/croniter/croniter.py", line 774, in expand
    return cls._expand(expr_format, hash_id=hash_id)
  File "/home/airflow/.local/lib/python3.7/site-packages/croniter/croniter.py", line 620, in _expand
    raise CroniterBadCronError(cls.bad_length)
croniter.croniter.CroniterBadCronError: Exactly 5 or 6 columns has to be specified for iterator expression.

During handling of the above exception, another exception occurred:

Traceback (most recent call last):
  File "/home/airflow/.local/lib/python3.7/site-packages/airflow/models/dagbag.py", line 405, in _process_modules
    dag.timetable.validate()
  File "/home/airflow/.local/lib/python3.7/site-packages/airflow/timetables/interval.py", line 175, in validate
    raise AirflowTimetableInvalid(str(e))
airflow.exceptions.AirflowTimetableInvalid: Exactly 5 or 6 columns has to be specified for iterator expression.
[2023-02-23 02:13:09,886] {processor.py:653} WARNING - No viable dags retrieved from /opt/airflow/dags/xray_test_dag.py
[2023-02-23 02:13:09,916] {processor.py:161} INFO - Processing /opt/airflow/dags/xray_test_dag.py took 0.057 seconds
[2023-02-23 02:13:39,994] {processor.py:153} INFO - Started process (PID=403) to work on /opt/airflow/dags/xray_test_dag.py
[2023-02-23 02:13:39,995] {processor.py:641} INFO - Processing file /opt/airflow/dags/xray_test_dag.py for tasks to queue
[2023-02-23 02:13:39,996] {logging_mixin.py:115} INFO - [2023-02-23 02:13:39,996] {dagbag.py:507} INFO - Filling up the DagBag from /opt/airflow/dags/xray_test_dag.py
[2023-02-23 02:13:40,012] {logging_mixin.py:115} INFO - [2023-02-23 02:13:40,011] {dagbag.py:412} ERROR - Failed to bag_dag: /opt/airflow/dags/xray_test_dag.py
Traceback (most recent call last):
  File "/home/airflow/.local/lib/python3.7/site-packages/airflow/timetables/interval.py", line 173, in validate
    croniter(self._expression)
  File "/home/airflow/.local/lib/python3.7/site-packages/croniter/croniter.py", line 166, in __init__
    self.expanded, self.nth_weekday_of_month = self.expand(expr_format, hash_id=hash_id)
  File "/home/airflow/.local/lib/python3.7/site-packages/croniter/croniter.py", line 774, in expand
    return cls._expand(expr_format, hash_id=hash_id)
  File "/home/airflow/.local/lib/python3.7/site-packages/croniter/croniter.py", line 620, in _expand
    raise CroniterBadCronError(cls.bad_length)
croniter.croniter.CroniterBadCronError: Exactly 5 or 6 columns has to be specified for iterator expression.

During handling of the above exception, another exception occurred:

Traceback (most recent call last):
  File "/home/airflow/.local/lib/python3.7/site-packages/airflow/models/dagbag.py", line 405, in _process_modules
    dag.timetable.validate()
  File "/home/airflow/.local/lib/python3.7/site-packages/airflow/timetables/interval.py", line 175, in validate
    raise AirflowTimetableInvalid(str(e))
airflow.exceptions.AirflowTimetableInvalid: Exactly 5 or 6 columns has to be specified for iterator expression.
[2023-02-23 02:13:40,012] {processor.py:653} WARNING - No viable dags retrieved from /opt/airflow/dags/xray_test_dag.py
[2023-02-23 02:13:40,033] {processor.py:161} INFO - Processing /opt/airflow/dags/xray_test_dag.py took 0.042 seconds
[2023-02-23 02:14:10,123] {processor.py:153} INFO - Started process (PID=408) to work on /opt/airflow/dags/xray_test_dag.py
[2023-02-23 02:14:10,124] {processor.py:641} INFO - Processing file /opt/airflow/dags/xray_test_dag.py for tasks to queue
[2023-02-23 02:14:10,125] {logging_mixin.py:115} INFO - [2023-02-23 02:14:10,125] {dagbag.py:507} INFO - Filling up the DagBag from /opt/airflow/dags/xray_test_dag.py
[2023-02-23 02:14:10,140] {logging_mixin.py:115} INFO - [2023-02-23 02:14:10,139] {dagbag.py:412} ERROR - Failed to bag_dag: /opt/airflow/dags/xray_test_dag.py
Traceback (most recent call last):
  File "/home/airflow/.local/lib/python3.7/site-packages/airflow/timetables/interval.py", line 173, in validate
    croniter(self._expression)
  File "/home/airflow/.local/lib/python3.7/site-packages/croniter/croniter.py", line 166, in __init__
    self.expanded, self.nth_weekday_of_month = self.expand(expr_format, hash_id=hash_id)
  File "/home/airflow/.local/lib/python3.7/site-packages/croniter/croniter.py", line 774, in expand
    return cls._expand(expr_format, hash_id=hash_id)
  File "/home/airflow/.local/lib/python3.7/site-packages/croniter/croniter.py", line 620, in _expand
    raise CroniterBadCronError(cls.bad_length)
croniter.croniter.CroniterBadCronError: Exactly 5 or 6 columns has to be specified for iterator expression.

During handling of the above exception, another exception occurred:

Traceback (most recent call last):
  File "/home/airflow/.local/lib/python3.7/site-packages/airflow/models/dagbag.py", line 405, in _process_modules
    dag.timetable.validate()
  File "/home/airflow/.local/lib/python3.7/site-packages/airflow/timetables/interval.py", line 175, in validate
    raise AirflowTimetableInvalid(str(e))
airflow.exceptions.AirflowTimetableInvalid: Exactly 5 or 6 columns has to be specified for iterator expression.
[2023-02-23 02:14:10,150] {processor.py:653} WARNING - No viable dags retrieved from /opt/airflow/dags/xray_test_dag.py
[2023-02-23 02:14:10,179] {processor.py:161} INFO - Processing /opt/airflow/dags/xray_test_dag.py took 0.058 seconds
[2023-02-23 02:14:40,227] {processor.py:153} INFO - Started process (PID=413) to work on /opt/airflow/dags/xray_test_dag.py
[2023-02-23 02:14:40,228] {processor.py:641} INFO - Processing file /opt/airflow/dags/xray_test_dag.py for tasks to queue
[2023-02-23 02:14:40,228] {logging_mixin.py:115} INFO - [2023-02-23 02:14:40,228] {dagbag.py:507} INFO - Filling up the DagBag from /opt/airflow/dags/xray_test_dag.py
[2023-02-23 02:14:40,243] {logging_mixin.py:115} INFO - [2023-02-23 02:14:40,242] {dagbag.py:412} ERROR - Failed to bag_dag: /opt/airflow/dags/xray_test_dag.py
Traceback (most recent call last):
  File "/home/airflow/.local/lib/python3.7/site-packages/airflow/timetables/interval.py", line 173, in validate
    croniter(self._expression)
  File "/home/airflow/.local/lib/python3.7/site-packages/croniter/croniter.py", line 166, in __init__
    self.expanded, self.nth_weekday_of_month = self.expand(expr_format, hash_id=hash_id)
  File "/home/airflow/.local/lib/python3.7/site-packages/croniter/croniter.py", line 774, in expand
    return cls._expand(expr_format, hash_id=hash_id)
  File "/home/airflow/.local/lib/python3.7/site-packages/croniter/croniter.py", line 620, in _expand
    raise CroniterBadCronError(cls.bad_length)
croniter.croniter.CroniterBadCronError: Exactly 5 or 6 columns has to be specified for iterator expression.

During handling of the above exception, another exception occurred:

Traceback (most recent call last):
  File "/home/airflow/.local/lib/python3.7/site-packages/airflow/models/dagbag.py", line 405, in _process_modules
    dag.timetable.validate()
  File "/home/airflow/.local/lib/python3.7/site-packages/airflow/timetables/interval.py", line 175, in validate
    raise AirflowTimetableInvalid(str(e))
airflow.exceptions.AirflowTimetableInvalid: Exactly 5 or 6 columns has to be specified for iterator expression.
[2023-02-23 02:14:40,243] {processor.py:653} WARNING - No viable dags retrieved from /opt/airflow/dags/xray_test_dag.py
[2023-02-23 02:14:40,273] {processor.py:161} INFO - Processing /opt/airflow/dags/xray_test_dag.py took 0.048 seconds
[2023-02-23 02:15:10,369] {processor.py:153} INFO - Started process (PID=418) to work on /opt/airflow/dags/xray_test_dag.py
[2023-02-23 02:15:10,370] {processor.py:641} INFO - Processing file /opt/airflow/dags/xray_test_dag.py for tasks to queue
[2023-02-23 02:15:10,370] {logging_mixin.py:115} INFO - [2023-02-23 02:15:10,370] {dagbag.py:507} INFO - Filling up the DagBag from /opt/airflow/dags/xray_test_dag.py
[2023-02-23 02:15:10,386] {logging_mixin.py:115} INFO - [2023-02-23 02:15:10,385] {dagbag.py:412} ERROR - Failed to bag_dag: /opt/airflow/dags/xray_test_dag.py
Traceback (most recent call last):
  File "/home/airflow/.local/lib/python3.7/site-packages/airflow/timetables/interval.py", line 173, in validate
    croniter(self._expression)
  File "/home/airflow/.local/lib/python3.7/site-packages/croniter/croniter.py", line 166, in __init__
    self.expanded, self.nth_weekday_of_month = self.expand(expr_format, hash_id=hash_id)
  File "/home/airflow/.local/lib/python3.7/site-packages/croniter/croniter.py", line 774, in expand
    return cls._expand(expr_format, hash_id=hash_id)
  File "/home/airflow/.local/lib/python3.7/site-packages/croniter/croniter.py", line 620, in _expand
    raise CroniterBadCronError(cls.bad_length)
croniter.croniter.CroniterBadCronError: Exactly 5 or 6 columns has to be specified for iterator expression.

During handling of the above exception, another exception occurred:

Traceback (most recent call last):
  File "/home/airflow/.local/lib/python3.7/site-packages/airflow/models/dagbag.py", line 405, in _process_modules
    dag.timetable.validate()
  File "/home/airflow/.local/lib/python3.7/site-packages/airflow/timetables/interval.py", line 175, in validate
    raise AirflowTimetableInvalid(str(e))
airflow.exceptions.AirflowTimetableInvalid: Exactly 5 or 6 columns has to be specified for iterator expression.
[2023-02-23 02:15:10,386] {processor.py:653} WARNING - No viable dags retrieved from /opt/airflow/dags/xray_test_dag.py
[2023-02-23 02:15:10,406] {processor.py:161} INFO - Processing /opt/airflow/dags/xray_test_dag.py took 0.040 seconds
[2023-02-23 02:15:40,474] {processor.py:153} INFO - Started process (PID=423) to work on /opt/airflow/dags/xray_test_dag.py
[2023-02-23 02:15:40,474] {processor.py:641} INFO - Processing file /opt/airflow/dags/xray_test_dag.py for tasks to queue
[2023-02-23 02:15:40,475] {logging_mixin.py:115} INFO - [2023-02-23 02:15:40,475] {dagbag.py:507} INFO - Filling up the DagBag from /opt/airflow/dags/xray_test_dag.py
[2023-02-23 02:15:40,491] {logging_mixin.py:115} INFO - [2023-02-23 02:15:40,490] {dagbag.py:412} ERROR - Failed to bag_dag: /opt/airflow/dags/xray_test_dag.py
Traceback (most recent call last):
  File "/home/airflow/.local/lib/python3.7/site-packages/airflow/timetables/interval.py", line 173, in validate
    croniter(self._expression)
  File "/home/airflow/.local/lib/python3.7/site-packages/croniter/croniter.py", line 166, in __init__
    self.expanded, self.nth_weekday_of_month = self.expand(expr_format, hash_id=hash_id)
  File "/home/airflow/.local/lib/python3.7/site-packages/croniter/croniter.py", line 774, in expand
    return cls._expand(expr_format, hash_id=hash_id)
  File "/home/airflow/.local/lib/python3.7/site-packages/croniter/croniter.py", line 620, in _expand
    raise CroniterBadCronError(cls.bad_length)
croniter.croniter.CroniterBadCronError: Exactly 5 or 6 columns has to be specified for iterator expression.

During handling of the above exception, another exception occurred:

Traceback (most recent call last):
  File "/home/airflow/.local/lib/python3.7/site-packages/airflow/models/dagbag.py", line 405, in _process_modules
    dag.timetable.validate()
  File "/home/airflow/.local/lib/python3.7/site-packages/airflow/timetables/interval.py", line 175, in validate
    raise AirflowTimetableInvalid(str(e))
airflow.exceptions.AirflowTimetableInvalid: Exactly 5 or 6 columns has to be specified for iterator expression.
[2023-02-23 02:15:40,491] {processor.py:653} WARNING - No viable dags retrieved from /opt/airflow/dags/xray_test_dag.py
[2023-02-23 02:15:40,510] {processor.py:161} INFO - Processing /opt/airflow/dags/xray_test_dag.py took 0.039 seconds
[2023-02-23 02:16:10,596] {processor.py:153} INFO - Started process (PID=428) to work on /opt/airflow/dags/xray_test_dag.py
[2023-02-23 02:16:10,596] {processor.py:641} INFO - Processing file /opt/airflow/dags/xray_test_dag.py for tasks to queue
[2023-02-23 02:16:10,597] {logging_mixin.py:115} INFO - [2023-02-23 02:16:10,597] {dagbag.py:507} INFO - Filling up the DagBag from /opt/airflow/dags/xray_test_dag.py
[2023-02-23 02:16:10,613] {logging_mixin.py:115} INFO - [2023-02-23 02:16:10,612] {dagbag.py:412} ERROR - Failed to bag_dag: /opt/airflow/dags/xray_test_dag.py
Traceback (most recent call last):
  File "/home/airflow/.local/lib/python3.7/site-packages/airflow/timetables/interval.py", line 173, in validate
    croniter(self._expression)
  File "/home/airflow/.local/lib/python3.7/site-packages/croniter/croniter.py", line 166, in __init__
    self.expanded, self.nth_weekday_of_month = self.expand(expr_format, hash_id=hash_id)
  File "/home/airflow/.local/lib/python3.7/site-packages/croniter/croniter.py", line 774, in expand
    return cls._expand(expr_format, hash_id=hash_id)
  File "/home/airflow/.local/lib/python3.7/site-packages/croniter/croniter.py", line 620, in _expand
    raise CroniterBadCronError(cls.bad_length)
croniter.croniter.CroniterBadCronError: Exactly 5 or 6 columns has to be specified for iterator expression.

During handling of the above exception, another exception occurred:

Traceback (most recent call last):
  File "/home/airflow/.local/lib/python3.7/site-packages/airflow/models/dagbag.py", line 405, in _process_modules
    dag.timetable.validate()
  File "/home/airflow/.local/lib/python3.7/site-packages/airflow/timetables/interval.py", line 175, in validate
    raise AirflowTimetableInvalid(str(e))
airflow.exceptions.AirflowTimetableInvalid: Exactly 5 or 6 columns has to be specified for iterator expression.
[2023-02-23 02:16:10,613] {processor.py:653} WARNING - No viable dags retrieved from /opt/airflow/dags/xray_test_dag.py
[2023-02-23 02:16:10,644] {processor.py:161} INFO - Processing /opt/airflow/dags/xray_test_dag.py took 0.051 seconds
[2023-02-23 02:16:17,625] {processor.py:153} INFO - Started process (PID=433) to work on /opt/airflow/dags/xray_test_dag.py
[2023-02-23 02:16:17,626] {processor.py:641} INFO - Processing file /opt/airflow/dags/xray_test_dag.py for tasks to queue
[2023-02-23 02:16:17,626] {logging_mixin.py:115} INFO - [2023-02-23 02:16:17,626] {dagbag.py:507} INFO - Filling up the DagBag from /opt/airflow/dags/xray_test_dag.py
[2023-02-23 02:16:17,651] {logging_mixin.py:115} INFO - [2023-02-23 02:16:17,650] {dagbag.py:412} ERROR - Failed to bag_dag: /opt/airflow/dags/xray_test_dag.py
Traceback (most recent call last):
  File "/home/airflow/.local/lib/python3.7/site-packages/croniter/croniter.py", line 172, in _alphaconv
    return cls.ALPHACONV[index][key]
KeyError: '?'

During handling of the above exception, another exception occurred:

Traceback (most recent call last):
  File "/home/airflow/.local/lib/python3.7/site-packages/airflow/timetables/interval.py", line 173, in validate
    croniter(self._expression)
  File "/home/airflow/.local/lib/python3.7/site-packages/croniter/croniter.py", line 166, in __init__
    self.expanded, self.nth_weekday_of_month = self.expand(expr_format, hash_id=hash_id)
  File "/home/airflow/.local/lib/python3.7/site-packages/croniter/croniter.py", line 774, in expand
    return cls._expand(expr_format, hash_id=hash_id)
  File "/home/airflow/.local/lib/python3.7/site-packages/croniter/croniter.py", line 717, in _expand
    t = cls._alphaconv(i, t, expressions)
  File "/home/airflow/.local/lib/python3.7/site-packages/croniter/croniter.py", line 175, in _alphaconv
    "[{0}] is not acceptable".format(" ".join(expressions)))
croniter.croniter.CroniterNotAlphaError: [0 0 4 ? *mon*] is not acceptable

During handling of the above exception, another exception occurred:

Traceback (most recent call last):
  File "/home/airflow/.local/lib/python3.7/site-packages/airflow/models/dagbag.py", line 405, in _process_modules
    dag.timetable.validate()
  File "/home/airflow/.local/lib/python3.7/site-packages/airflow/timetables/interval.py", line 175, in validate
    raise AirflowTimetableInvalid(str(e))
airflow.exceptions.AirflowTimetableInvalid: [0 0 4 ? *mon*] is not acceptable
[2023-02-23 02:16:17,651] {processor.py:653} WARNING - No viable dags retrieved from /opt/airflow/dags/xray_test_dag.py
[2023-02-23 02:16:17,682] {processor.py:161} INFO - Processing /opt/airflow/dags/xray_test_dag.py took 0.060 seconds
[2023-02-23 02:16:47,778] {processor.py:153} INFO - Started process (PID=438) to work on /opt/airflow/dags/xray_test_dag.py
[2023-02-23 02:16:47,779] {processor.py:641} INFO - Processing file /opt/airflow/dags/xray_test_dag.py for tasks to queue
[2023-02-23 02:16:47,780] {logging_mixin.py:115} INFO - [2023-02-23 02:16:47,780] {dagbag.py:507} INFO - Filling up the DagBag from /opt/airflow/dags/xray_test_dag.py
[2023-02-23 02:16:47,796] {logging_mixin.py:115} INFO - [2023-02-23 02:16:47,794] {dagbag.py:412} ERROR - Failed to bag_dag: /opt/airflow/dags/xray_test_dag.py
Traceback (most recent call last):
  File "/home/airflow/.local/lib/python3.7/site-packages/croniter/croniter.py", line 172, in _alphaconv
    return cls.ALPHACONV[index][key]
KeyError: '?'

During handling of the above exception, another exception occurred:

Traceback (most recent call last):
  File "/home/airflow/.local/lib/python3.7/site-packages/airflow/timetables/interval.py", line 173, in validate
    croniter(self._expression)
  File "/home/airflow/.local/lib/python3.7/site-packages/croniter/croniter.py", line 166, in __init__
    self.expanded, self.nth_weekday_of_month = self.expand(expr_format, hash_id=hash_id)
  File "/home/airflow/.local/lib/python3.7/site-packages/croniter/croniter.py", line 774, in expand
    return cls._expand(expr_format, hash_id=hash_id)
  File "/home/airflow/.local/lib/python3.7/site-packages/croniter/croniter.py", line 717, in _expand
    t = cls._alphaconv(i, t, expressions)
  File "/home/airflow/.local/lib/python3.7/site-packages/croniter/croniter.py", line 175, in _alphaconv
    "[{0}] is not acceptable".format(" ".join(expressions)))
croniter.croniter.CroniterNotAlphaError: [0 0 4 ? *mon*] is not acceptable

During handling of the above exception, another exception occurred:

Traceback (most recent call last):
  File "/home/airflow/.local/lib/python3.7/site-packages/airflow/models/dagbag.py", line 405, in _process_modules
    dag.timetable.validate()
  File "/home/airflow/.local/lib/python3.7/site-packages/airflow/timetables/interval.py", line 175, in validate
    raise AirflowTimetableInvalid(str(e))
airflow.exceptions.AirflowTimetableInvalid: [0 0 4 ? *mon*] is not acceptable
[2023-02-23 02:16:47,796] {processor.py:653} WARNING - No viable dags retrieved from /opt/airflow/dags/xray_test_dag.py
[2023-02-23 02:16:47,827] {processor.py:161} INFO - Processing /opt/airflow/dags/xray_test_dag.py took 0.051 seconds
[2023-02-23 02:17:17,883] {processor.py:153} INFO - Started process (PID=443) to work on /opt/airflow/dags/xray_test_dag.py
[2023-02-23 02:17:17,883] {processor.py:641} INFO - Processing file /opt/airflow/dags/xray_test_dag.py for tasks to queue
[2023-02-23 02:17:17,884] {logging_mixin.py:115} INFO - [2023-02-23 02:17:17,884] {dagbag.py:507} INFO - Filling up the DagBag from /opt/airflow/dags/xray_test_dag.py
[2023-02-23 02:17:17,900] {logging_mixin.py:115} INFO - [2023-02-23 02:17:17,899] {dagbag.py:412} ERROR - Failed to bag_dag: /opt/airflow/dags/xray_test_dag.py
Traceback (most recent call last):
  File "/home/airflow/.local/lib/python3.7/site-packages/croniter/croniter.py", line 172, in _alphaconv
    return cls.ALPHACONV[index][key]
KeyError: '?'

During handling of the above exception, another exception occurred:

Traceback (most recent call last):
  File "/home/airflow/.local/lib/python3.7/site-packages/airflow/timetables/interval.py", line 173, in validate
    croniter(self._expression)
  File "/home/airflow/.local/lib/python3.7/site-packages/croniter/croniter.py", line 166, in __init__
    self.expanded, self.nth_weekday_of_month = self.expand(expr_format, hash_id=hash_id)
  File "/home/airflow/.local/lib/python3.7/site-packages/croniter/croniter.py", line 774, in expand
    return cls._expand(expr_format, hash_id=hash_id)
  File "/home/airflow/.local/lib/python3.7/site-packages/croniter/croniter.py", line 717, in _expand
    t = cls._alphaconv(i, t, expressions)
  File "/home/airflow/.local/lib/python3.7/site-packages/croniter/croniter.py", line 175, in _alphaconv
    "[{0}] is not acceptable".format(" ".join(expressions)))
croniter.croniter.CroniterNotAlphaError: [0 0 4 ? *mon*] is not acceptable

During handling of the above exception, another exception occurred:

Traceback (most recent call last):
  File "/home/airflow/.local/lib/python3.7/site-packages/airflow/models/dagbag.py", line 405, in _process_modules
    dag.timetable.validate()
  File "/home/airflow/.local/lib/python3.7/site-packages/airflow/timetables/interval.py", line 175, in validate
    raise AirflowTimetableInvalid(str(e))
airflow.exceptions.AirflowTimetableInvalid: [0 0 4 ? *mon*] is not acceptable
[2023-02-23 02:17:17,901] {processor.py:653} WARNING - No viable dags retrieved from /opt/airflow/dags/xray_test_dag.py
[2023-02-23 02:17:17,920] {processor.py:161} INFO - Processing /opt/airflow/dags/xray_test_dag.py took 0.040 seconds
[2023-02-23 02:17:48,014] {processor.py:153} INFO - Started process (PID=448) to work on /opt/airflow/dags/xray_test_dag.py
[2023-02-23 02:17:48,014] {processor.py:641} INFO - Processing file /opt/airflow/dags/xray_test_dag.py for tasks to queue
[2023-02-23 02:17:48,015] {logging_mixin.py:115} INFO - [2023-02-23 02:17:48,015] {dagbag.py:507} INFO - Filling up the DagBag from /opt/airflow/dags/xray_test_dag.py
[2023-02-23 02:17:48,030] {logging_mixin.py:115} INFO - [2023-02-23 02:17:48,029] {dagbag.py:412} ERROR - Failed to bag_dag: /opt/airflow/dags/xray_test_dag.py
Traceback (most recent call last):
  File "/home/airflow/.local/lib/python3.7/site-packages/croniter/croniter.py", line 172, in _alphaconv
    return cls.ALPHACONV[index][key]
KeyError: '?'

During handling of the above exception, another exception occurred:

Traceback (most recent call last):
  File "/home/airflow/.local/lib/python3.7/site-packages/airflow/timetables/interval.py", line 173, in validate
    croniter(self._expression)
  File "/home/airflow/.local/lib/python3.7/site-packages/croniter/croniter.py", line 166, in __init__
    self.expanded, self.nth_weekday_of_month = self.expand(expr_format, hash_id=hash_id)
  File "/home/airflow/.local/lib/python3.7/site-packages/croniter/croniter.py", line 774, in expand
    return cls._expand(expr_format, hash_id=hash_id)
  File "/home/airflow/.local/lib/python3.7/site-packages/croniter/croniter.py", line 717, in _expand
    t = cls._alphaconv(i, t, expressions)
  File "/home/airflow/.local/lib/python3.7/site-packages/croniter/croniter.py", line 175, in _alphaconv
    "[{0}] is not acceptable".format(" ".join(expressions)))
croniter.croniter.CroniterNotAlphaError: [0 0 4 ? *mon*] is not acceptable

During handling of the above exception, another exception occurred:

Traceback (most recent call last):
  File "/home/airflow/.local/lib/python3.7/site-packages/airflow/models/dagbag.py", line 405, in _process_modules
    dag.timetable.validate()
  File "/home/airflow/.local/lib/python3.7/site-packages/airflow/timetables/interval.py", line 175, in validate
    raise AirflowTimetableInvalid(str(e))
airflow.exceptions.AirflowTimetableInvalid: [0 0 4 ? *mon*] is not acceptable
[2023-02-23 02:17:48,030] {processor.py:653} WARNING - No viable dags retrieved from /opt/airflow/dags/xray_test_dag.py
[2023-02-23 02:17:48,049] {processor.py:161} INFO - Processing /opt/airflow/dags/xray_test_dag.py took 0.037 seconds
[2023-02-23 02:18:18,119] {processor.py:153} INFO - Started process (PID=453) to work on /opt/airflow/dags/xray_test_dag.py
[2023-02-23 02:18:18,120] {processor.py:641} INFO - Processing file /opt/airflow/dags/xray_test_dag.py for tasks to queue
[2023-02-23 02:18:18,120] {logging_mixin.py:115} INFO - [2023-02-23 02:18:18,120] {dagbag.py:507} INFO - Filling up the DagBag from /opt/airflow/dags/xray_test_dag.py
[2023-02-23 02:18:18,141] {logging_mixin.py:115} INFO - [2023-02-23 02:18:18,139] {dagbag.py:412} ERROR - Failed to bag_dag: /opt/airflow/dags/xray_test_dag.py
Traceback (most recent call last):
  File "/home/airflow/.local/lib/python3.7/site-packages/croniter/croniter.py", line 172, in _alphaconv
    return cls.ALPHACONV[index][key]
KeyError: '?'

During handling of the above exception, another exception occurred:

Traceback (most recent call last):
  File "/home/airflow/.local/lib/python3.7/site-packages/airflow/timetables/interval.py", line 173, in validate
    croniter(self._expression)
  File "/home/airflow/.local/lib/python3.7/site-packages/croniter/croniter.py", line 166, in __init__
    self.expanded, self.nth_weekday_of_month = self.expand(expr_format, hash_id=hash_id)
  File "/home/airflow/.local/lib/python3.7/site-packages/croniter/croniter.py", line 774, in expand
    return cls._expand(expr_format, hash_id=hash_id)
  File "/home/airflow/.local/lib/python3.7/site-packages/croniter/croniter.py", line 717, in _expand
    t = cls._alphaconv(i, t, expressions)
  File "/home/airflow/.local/lib/python3.7/site-packages/croniter/croniter.py", line 175, in _alphaconv
    "[{0}] is not acceptable".format(" ".join(expressions)))
croniter.croniter.CroniterNotAlphaError: [0 0 4 ? *mon*] is not acceptable

During handling of the above exception, another exception occurred:

Traceback (most recent call last):
  File "/home/airflow/.local/lib/python3.7/site-packages/airflow/models/dagbag.py", line 405, in _process_modules
    dag.timetable.validate()
  File "/home/airflow/.local/lib/python3.7/site-packages/airflow/timetables/interval.py", line 175, in validate
    raise AirflowTimetableInvalid(str(e))
airflow.exceptions.AirflowTimetableInvalid: [0 0 4 ? *mon*] is not acceptable
[2023-02-23 02:18:18,141] {processor.py:653} WARNING - No viable dags retrieved from /opt/airflow/dags/xray_test_dag.py
[2023-02-23 02:18:18,163] {processor.py:161} INFO - Processing /opt/airflow/dags/xray_test_dag.py took 0.047 seconds
[2023-02-23 02:18:27,169] {processor.py:153} INFO - Started process (PID=458) to work on /opt/airflow/dags/xray_test_dag.py
[2023-02-23 02:18:27,170] {processor.py:641} INFO - Processing file /opt/airflow/dags/xray_test_dag.py for tasks to queue
[2023-02-23 02:18:27,171] {logging_mixin.py:115} INFO - [2023-02-23 02:18:27,171] {dagbag.py:507} INFO - Filling up the DagBag from /opt/airflow/dags/xray_test_dag.py
[2023-02-23 02:18:27,195] {logging_mixin.py:115} INFO - [2023-02-23 02:18:27,194] {dagbag.py:412} ERROR - Failed to bag_dag: /opt/airflow/dags/xray_test_dag.py
Traceback (most recent call last):
  File "/home/airflow/.local/lib/python3.7/site-packages/airflow/timetables/interval.py", line 173, in validate
    croniter(self._expression)
  File "/home/airflow/.local/lib/python3.7/site-packages/croniter/croniter.py", line 166, in __init__
    self.expanded, self.nth_weekday_of_month = self.expand(expr_format, hash_id=hash_id)
  File "/home/airflow/.local/lib/python3.7/site-packages/croniter/croniter.py", line 774, in expand
    return cls._expand(expr_format, hash_id=hash_id)
  File "/home/airflow/.local/lib/python3.7/site-packages/croniter/croniter.py", line 620, in _expand
    raise CroniterBadCronError(cls.bad_length)
croniter.croniter.CroniterBadCronError: Exactly 5 or 6 columns has to be specified for iterator expression.

During handling of the above exception, another exception occurred:

Traceback (most recent call last):
  File "/home/airflow/.local/lib/python3.7/site-packages/airflow/models/dagbag.py", line 405, in _process_modules
    dag.timetable.validate()
  File "/home/airflow/.local/lib/python3.7/site-packages/airflow/timetables/interval.py", line 175, in validate
    raise AirflowTimetableInvalid(str(e))
airflow.exceptions.AirflowTimetableInvalid: Exactly 5 or 6 columns has to be specified for iterator expression.
[2023-02-23 02:18:27,195] {processor.py:653} WARNING - No viable dags retrieved from /opt/airflow/dags/xray_test_dag.py
[2023-02-23 02:18:27,212] {processor.py:161} INFO - Processing /opt/airflow/dags/xray_test_dag.py took 0.046 seconds
[2023-02-23 02:18:57,325] {processor.py:153} INFO - Started process (PID=463) to work on /opt/airflow/dags/xray_test_dag.py
[2023-02-23 02:18:57,325] {processor.py:641} INFO - Processing file /opt/airflow/dags/xray_test_dag.py for tasks to queue
[2023-02-23 02:18:57,326] {logging_mixin.py:115} INFO - [2023-02-23 02:18:57,326] {dagbag.py:507} INFO - Filling up the DagBag from /opt/airflow/dags/xray_test_dag.py
[2023-02-23 02:18:57,343] {logging_mixin.py:115} INFO - [2023-02-23 02:18:57,342] {dagbag.py:412} ERROR - Failed to bag_dag: /opt/airflow/dags/xray_test_dag.py
Traceback (most recent call last):
  File "/home/airflow/.local/lib/python3.7/site-packages/airflow/timetables/interval.py", line 173, in validate
    croniter(self._expression)
  File "/home/airflow/.local/lib/python3.7/site-packages/croniter/croniter.py", line 166, in __init__
    self.expanded, self.nth_weekday_of_month = self.expand(expr_format, hash_id=hash_id)
  File "/home/airflow/.local/lib/python3.7/site-packages/croniter/croniter.py", line 774, in expand
    return cls._expand(expr_format, hash_id=hash_id)
  File "/home/airflow/.local/lib/python3.7/site-packages/croniter/croniter.py", line 620, in _expand
    raise CroniterBadCronError(cls.bad_length)
croniter.croniter.CroniterBadCronError: Exactly 5 or 6 columns has to be specified for iterator expression.

During handling of the above exception, another exception occurred:

Traceback (most recent call last):
  File "/home/airflow/.local/lib/python3.7/site-packages/airflow/models/dagbag.py", line 405, in _process_modules
    dag.timetable.validate()
  File "/home/airflow/.local/lib/python3.7/site-packages/airflow/timetables/interval.py", line 175, in validate
    raise AirflowTimetableInvalid(str(e))
airflow.exceptions.AirflowTimetableInvalid: Exactly 5 or 6 columns has to be specified for iterator expression.
[2023-02-23 02:18:57,343] {processor.py:653} WARNING - No viable dags retrieved from /opt/airflow/dags/xray_test_dag.py
[2023-02-23 02:18:57,373] {processor.py:161} INFO - Processing /opt/airflow/dags/xray_test_dag.py took 0.051 seconds
[2023-02-23 02:19:11,378] {processor.py:153} INFO - Started process (PID=468) to work on /opt/airflow/dags/xray_test_dag.py
[2023-02-23 02:19:11,378] {processor.py:641} INFO - Processing file /opt/airflow/dags/xray_test_dag.py for tasks to queue
[2023-02-23 02:19:11,379] {logging_mixin.py:115} INFO - [2023-02-23 02:19:11,379] {dagbag.py:507} INFO - Filling up the DagBag from /opt/airflow/dags/xray_test_dag.py
[2023-02-23 02:19:11,404] {processor.py:651} INFO - DAG(s) dict_keys(['xray']) retrieved from /opt/airflow/dags/xray_test_dag.py
[2023-02-23 02:19:11,501] {logging_mixin.py:115} INFO - [2023-02-23 02:19:11,501] {manager.py:508} INFO - Created Permission View: can delete on DAG:xray
[2023-02-23 02:19:11,511] {logging_mixin.py:115} INFO - [2023-02-23 02:19:11,511] {manager.py:508} INFO - Created Permission View: can edit on DAG:xray
[2023-02-23 02:19:11,519] {logging_mixin.py:115} INFO - [2023-02-23 02:19:11,519] {manager.py:508} INFO - Created Permission View: can read on DAG:xray
[2023-02-23 02:19:11,520] {logging_mixin.py:115} INFO - [2023-02-23 02:19:11,520] {dag.py:2371} INFO - Sync 1 DAGs
[2023-02-23 02:19:11,529] {logging_mixin.py:115} INFO - [2023-02-23 02:19:11,529] {dag.py:2390} INFO - Creating ORM DAG for xray
[2023-02-23 02:19:11,543] {logging_mixin.py:115} INFO - [2023-02-23 02:19:11,543] {dag.py:2919} INFO - Setting next_dagrun for xray to 2023-02-20T00:00:58+00:00, run_after=2023-02-20T00:00:59+00:00
[2023-02-23 02:19:11,559] {processor.py:161} INFO - Processing /opt/airflow/dags/xray_test_dag.py took 0.184 seconds
[2023-02-23 02:19:41,659] {processor.py:153} INFO - Started process (PID=473) to work on /opt/airflow/dags/xray_test_dag.py
[2023-02-23 02:19:41,659] {processor.py:641} INFO - Processing file /opt/airflow/dags/xray_test_dag.py for tasks to queue
[2023-02-23 02:19:41,660] {logging_mixin.py:115} INFO - [2023-02-23 02:19:41,660] {dagbag.py:507} INFO - Filling up the DagBag from /opt/airflow/dags/xray_test_dag.py
[2023-02-23 02:19:41,676] {processor.py:651} INFO - DAG(s) dict_keys(['xray']) retrieved from /opt/airflow/dags/xray_test_dag.py
[2023-02-23 02:19:41,703] {logging_mixin.py:115} INFO - [2023-02-23 02:19:41,702] {dag.py:2371} INFO - Sync 1 DAGs
[2023-02-23 02:19:41,724] {logging_mixin.py:115} INFO - [2023-02-23 02:19:41,723] {dag.py:2919} INFO - Setting next_dagrun for xray to 2023-02-20T00:00:58+00:00, run_after=2023-02-20T00:00:59+00:00
[2023-02-23 02:19:41,735] {processor.py:161} INFO - Processing /opt/airflow/dags/xray_test_dag.py took 0.079 seconds
[2023-02-23 02:20:11,769] {processor.py:153} INFO - Started process (PID=478) to work on /opt/airflow/dags/xray_test_dag.py
[2023-02-23 02:20:11,770] {processor.py:641} INFO - Processing file /opt/airflow/dags/xray_test_dag.py for tasks to queue
[2023-02-23 02:20:11,771] {logging_mixin.py:115} INFO - [2023-02-23 02:20:11,771] {dagbag.py:507} INFO - Filling up the DagBag from /opt/airflow/dags/xray_test_dag.py
[2023-02-23 02:20:11,790] {processor.py:651} INFO - DAG(s) dict_keys(['xray']) retrieved from /opt/airflow/dags/xray_test_dag.py
[2023-02-23 02:20:11,816] {logging_mixin.py:115} INFO - [2023-02-23 02:20:11,816] {dag.py:2371} INFO - Sync 1 DAGs
[2023-02-23 02:20:11,837] {logging_mixin.py:115} INFO - [2023-02-23 02:20:11,837] {dag.py:2919} INFO - Setting next_dagrun for xray to 2023-02-20T00:00:58+00:00, run_after=2023-02-20T00:00:59+00:00
[2023-02-23 02:20:11,849] {processor.py:161} INFO - Processing /opt/airflow/dags/xray_test_dag.py took 0.082 seconds
[2023-02-23 02:20:41,929] {processor.py:153} INFO - Started process (PID=483) to work on /opt/airflow/dags/xray_test_dag.py
[2023-02-23 02:20:41,930] {processor.py:641} INFO - Processing file /opt/airflow/dags/xray_test_dag.py for tasks to queue
[2023-02-23 02:20:41,931] {logging_mixin.py:115} INFO - [2023-02-23 02:20:41,931] {dagbag.py:507} INFO - Filling up the DagBag from /opt/airflow/dags/xray_test_dag.py
[2023-02-23 02:20:41,951] {processor.py:651} INFO - DAG(s) dict_keys(['xray']) retrieved from /opt/airflow/dags/xray_test_dag.py
[2023-02-23 02:20:41,998] {logging_mixin.py:115} INFO - [2023-02-23 02:20:41,997] {dag.py:2371} INFO - Sync 1 DAGs
[2023-02-23 02:20:42,032] {logging_mixin.py:115} INFO - [2023-02-23 02:20:42,032] {dag.py:2919} INFO - Setting next_dagrun for xray to 2023-02-20T00:00:58+00:00, run_after=2023-02-20T00:00:59+00:00
[2023-02-23 02:20:42,048] {processor.py:161} INFO - Processing /opt/airflow/dags/xray_test_dag.py took 0.121 seconds
[2023-02-23 02:21:12,139] {processor.py:153} INFO - Started process (PID=488) to work on /opt/airflow/dags/xray_test_dag.py
[2023-02-23 02:21:12,139] {processor.py:641} INFO - Processing file /opt/airflow/dags/xray_test_dag.py for tasks to queue
[2023-02-23 02:21:12,140] {logging_mixin.py:115} INFO - [2023-02-23 02:21:12,140] {dagbag.py:507} INFO - Filling up the DagBag from /opt/airflow/dags/xray_test_dag.py
[2023-02-23 02:21:12,156] {processor.py:651} INFO - DAG(s) dict_keys(['xray']) retrieved from /opt/airflow/dags/xray_test_dag.py
[2023-02-23 02:21:12,181] {logging_mixin.py:115} INFO - [2023-02-23 02:21:12,181] {dag.py:2371} INFO - Sync 1 DAGs
[2023-02-23 02:21:12,202] {logging_mixin.py:115} INFO - [2023-02-23 02:21:12,202] {dag.py:2919} INFO - Setting next_dagrun for xray to 2023-02-20T00:00:58+00:00, run_after=2023-02-20T00:00:59+00:00
[2023-02-23 02:21:12,213] {processor.py:161} INFO - Processing /opt/airflow/dags/xray_test_dag.py took 0.077 seconds
[2023-02-23 02:21:42,239] {processor.py:153} INFO - Started process (PID=493) to work on /opt/airflow/dags/xray_test_dag.py
[2023-02-23 02:21:42,240] {processor.py:641} INFO - Processing file /opt/airflow/dags/xray_test_dag.py for tasks to queue
[2023-02-23 02:21:42,241] {logging_mixin.py:115} INFO - [2023-02-23 02:21:42,241] {dagbag.py:507} INFO - Filling up the DagBag from /opt/airflow/dags/xray_test_dag.py
[2023-02-23 02:21:42,256] {processor.py:651} INFO - DAG(s) dict_keys(['xray']) retrieved from /opt/airflow/dags/xray_test_dag.py
[2023-02-23 02:21:42,282] {logging_mixin.py:115} INFO - [2023-02-23 02:21:42,281] {dag.py:2371} INFO - Sync 1 DAGs
[2023-02-23 02:21:42,303] {logging_mixin.py:115} INFO - [2023-02-23 02:21:42,303] {dag.py:2919} INFO - Setting next_dagrun for xray to 2023-02-20T00:00:58+00:00, run_after=2023-02-20T00:00:59+00:00
[2023-02-23 02:21:42,314] {processor.py:161} INFO - Processing /opt/airflow/dags/xray_test_dag.py took 0.077 seconds
[2023-02-23 02:22:12,402] {processor.py:153} INFO - Started process (PID=498) to work on /opt/airflow/dags/xray_test_dag.py
[2023-02-23 02:22:12,402] {processor.py:641} INFO - Processing file /opt/airflow/dags/xray_test_dag.py for tasks to queue
[2023-02-23 02:22:12,403] {logging_mixin.py:115} INFO - [2023-02-23 02:22:12,403] {dagbag.py:507} INFO - Filling up the DagBag from /opt/airflow/dags/xray_test_dag.py
[2023-02-23 02:22:12,419] {processor.py:651} INFO - DAG(s) dict_keys(['xray']) retrieved from /opt/airflow/dags/xray_test_dag.py
[2023-02-23 02:22:12,446] {logging_mixin.py:115} INFO - [2023-02-23 02:22:12,446] {dag.py:2371} INFO - Sync 1 DAGs
[2023-02-23 02:22:12,468] {logging_mixin.py:115} INFO - [2023-02-23 02:22:12,468] {dag.py:2919} INFO - Setting next_dagrun for xray to 2023-02-20T00:00:58+00:00, run_after=2023-02-20T00:00:59+00:00
[2023-02-23 02:22:12,490] {processor.py:161} INFO - Processing /opt/airflow/dags/xray_test_dag.py took 0.091 seconds
[2023-02-23 02:22:34,483] {processor.py:153} INFO - Started process (PID=503) to work on /opt/airflow/dags/xray_test_dag.py
[2023-02-23 02:22:34,484] {processor.py:641} INFO - Processing file /opt/airflow/dags/xray_test_dag.py for tasks to queue
[2023-02-23 02:22:34,484] {logging_mixin.py:115} INFO - [2023-02-23 02:22:34,484] {dagbag.py:507} INFO - Filling up the DagBag from /opt/airflow/dags/xray_test_dag.py
[2023-02-23 02:22:34,511] {logging_mixin.py:115} INFO - [2023-02-23 02:22:34,507] {dagbag.py:320} ERROR - Failed to import: /opt/airflow/dags/xray_test_dag.py
Traceback (most recent call last):
  File "/home/airflow/.local/lib/python3.7/site-packages/airflow/models/dagbag.py", line 317, in parse
    loader.exec_module(new_module)
  File "<frozen importlib._bootstrap_external>", line 728, in exec_module
  File "<frozen importlib._bootstrap>", line 219, in _call_with_frames_removed
  File "/opt/airflow/dags/xray_test_dag.py", line 63, in <module>
    task_id= 'put_database_record'
  File "/home/airflow/.local/lib/python3.7/site-packages/airflow/models/baseoperator.py", line 390, in apply_defaults
    result = func(self, **kwargs, default_args=default_args)
  File "/home/airflow/.local/lib/python3.7/site-packages/airflow/models/baseoperator.py", line 390, in apply_defaults
    result = func(self, **kwargs, default_args=default_args)
  File "/home/airflow/.local/lib/python3.7/site-packages/airflow/models/baseoperator.py", line 764, in __init__
    task_group.add(self)
  File "/home/airflow/.local/lib/python3.7/site-packages/airflow/utils/task_group.py", line 196, in add
    raise DuplicateTaskIdFound(f"{node_type} id '{key}' has already been added to the DAG")
airflow.exceptions.DuplicateTaskIdFound: Task id 'put_database_record' has already been added to the DAG
[2023-02-23 02:22:34,512] {processor.py:653} WARNING - No viable dags retrieved from /opt/airflow/dags/xray_test_dag.py
[2023-02-23 02:22:34,544] {processor.py:161} INFO - Processing /opt/airflow/dags/xray_test_dag.py took 0.063 seconds
[2023-02-23 02:23:04,590] {processor.py:153} INFO - Started process (PID=508) to work on /opt/airflow/dags/xray_test_dag.py
[2023-02-23 02:23:04,591] {processor.py:641} INFO - Processing file /opt/airflow/dags/xray_test_dag.py for tasks to queue
[2023-02-23 02:23:04,591] {logging_mixin.py:115} INFO - [2023-02-23 02:23:04,591] {dagbag.py:507} INFO - Filling up the DagBag from /opt/airflow/dags/xray_test_dag.py
[2023-02-23 02:23:04,609] {logging_mixin.py:115} INFO - [2023-02-23 02:23:04,605] {dagbag.py:320} ERROR - Failed to import: /opt/airflow/dags/xray_test_dag.py
Traceback (most recent call last):
  File "/home/airflow/.local/lib/python3.7/site-packages/airflow/models/dagbag.py", line 317, in parse
    loader.exec_module(new_module)
  File "<frozen importlib._bootstrap_external>", line 728, in exec_module
  File "<frozen importlib._bootstrap>", line 219, in _call_with_frames_removed
  File "/opt/airflow/dags/xray_test_dag.py", line 63, in <module>
    task_id= 'put_database_record'
  File "/home/airflow/.local/lib/python3.7/site-packages/airflow/models/baseoperator.py", line 390, in apply_defaults
    result = func(self, **kwargs, default_args=default_args)
  File "/home/airflow/.local/lib/python3.7/site-packages/airflow/models/baseoperator.py", line 390, in apply_defaults
    result = func(self, **kwargs, default_args=default_args)
  File "/home/airflow/.local/lib/python3.7/site-packages/airflow/models/baseoperator.py", line 764, in __init__
    task_group.add(self)
  File "/home/airflow/.local/lib/python3.7/site-packages/airflow/utils/task_group.py", line 196, in add
    raise DuplicateTaskIdFound(f"{node_type} id '{key}' has already been added to the DAG")
airflow.exceptions.DuplicateTaskIdFound: Task id 'put_database_record' has already been added to the DAG
[2023-02-23 02:23:04,610] {processor.py:653} WARNING - No viable dags retrieved from /opt/airflow/dags/xray_test_dag.py
[2023-02-23 02:23:04,640] {processor.py:161} INFO - Processing /opt/airflow/dags/xray_test_dag.py took 0.052 seconds
[2023-02-23 02:23:18,687] {processor.py:153} INFO - Started process (PID=513) to work on /opt/airflow/dags/xray_test_dag.py
[2023-02-23 02:23:18,688] {processor.py:641} INFO - Processing file /opt/airflow/dags/xray_test_dag.py for tasks to queue
[2023-02-23 02:23:18,688] {logging_mixin.py:115} INFO - [2023-02-23 02:23:18,688] {dagbag.py:507} INFO - Filling up the DagBag from /opt/airflow/dags/xray_test_dag.py
[2023-02-23 02:23:18,712] {processor.py:651} INFO - DAG(s) dict_keys(['xray']) retrieved from /opt/airflow/dags/xray_test_dag.py
[2023-02-23 02:23:18,782] {logging_mixin.py:115} INFO - [2023-02-23 02:23:18,782] {dag.py:2371} INFO - Sync 1 DAGs
[2023-02-23 02:23:18,805] {logging_mixin.py:115} INFO - [2023-02-23 02:23:18,804] {dag.py:2919} INFO - Setting next_dagrun for xray to 2023-02-20T00:00:58+00:00, run_after=2023-02-20T00:00:59+00:00
[2023-02-23 02:23:18,824] {processor.py:161} INFO - Processing /opt/airflow/dags/xray_test_dag.py took 0.140 seconds
[2023-02-23 02:23:48,914] {processor.py:153} INFO - Started process (PID=518) to work on /opt/airflow/dags/xray_test_dag.py
[2023-02-23 02:23:48,915] {processor.py:641} INFO - Processing file /opt/airflow/dags/xray_test_dag.py for tasks to queue
[2023-02-23 02:23:48,916] {logging_mixin.py:115} INFO - [2023-02-23 02:23:48,916] {dagbag.py:507} INFO - Filling up the DagBag from /opt/airflow/dags/xray_test_dag.py
[2023-02-23 02:23:48,932] {processor.py:651} INFO - DAG(s) dict_keys(['xray']) retrieved from /opt/airflow/dags/xray_test_dag.py
[2023-02-23 02:23:48,958] {logging_mixin.py:115} INFO - [2023-02-23 02:23:48,958] {dag.py:2371} INFO - Sync 1 DAGs
[2023-02-23 02:23:48,981] {logging_mixin.py:115} INFO - [2023-02-23 02:23:48,981] {dag.py:2919} INFO - Setting next_dagrun for xray to 2023-02-20T00:00:58+00:00, run_after=2023-02-20T00:00:59+00:00
[2023-02-23 02:23:49,005] {processor.py:161} INFO - Processing /opt/airflow/dags/xray_test_dag.py took 0.093 seconds
[2023-02-23 02:24:19,043] {processor.py:153} INFO - Started process (PID=523) to work on /opt/airflow/dags/xray_test_dag.py
[2023-02-23 02:24:19,044] {processor.py:641} INFO - Processing file /opt/airflow/dags/xray_test_dag.py for tasks to queue
[2023-02-23 02:24:19,044] {logging_mixin.py:115} INFO - [2023-02-23 02:24:19,044] {dagbag.py:507} INFO - Filling up the DagBag from /opt/airflow/dags/xray_test_dag.py
[2023-02-23 02:24:19,062] {processor.py:651} INFO - DAG(s) dict_keys(['xray']) retrieved from /opt/airflow/dags/xray_test_dag.py
[2023-02-23 02:24:19,094] {logging_mixin.py:115} INFO - [2023-02-23 02:24:19,094] {dag.py:2371} INFO - Sync 1 DAGs
[2023-02-23 02:24:19,120] {logging_mixin.py:115} INFO - [2023-02-23 02:24:19,120] {dag.py:2919} INFO - Setting next_dagrun for xray to 2023-02-20T00:00:58+00:00, run_after=2023-02-20T00:00:59+00:00
[2023-02-23 02:24:19,131] {processor.py:161} INFO - Processing /opt/airflow/dags/xray_test_dag.py took 0.092 seconds
[2023-02-23 02:24:49,195] {processor.py:153} INFO - Started process (PID=528) to work on /opt/airflow/dags/xray_test_dag.py
[2023-02-23 02:24:49,195] {processor.py:641} INFO - Processing file /opt/airflow/dags/xray_test_dag.py for tasks to queue
[2023-02-23 02:24:49,196] {logging_mixin.py:115} INFO - [2023-02-23 02:24:49,196] {dagbag.py:507} INFO - Filling up the DagBag from /opt/airflow/dags/xray_test_dag.py
[2023-02-23 02:24:49,212] {processor.py:651} INFO - DAG(s) dict_keys(['xray']) retrieved from /opt/airflow/dags/xray_test_dag.py
[2023-02-23 02:24:49,238] {logging_mixin.py:115} INFO - [2023-02-23 02:24:49,238] {dag.py:2371} INFO - Sync 1 DAGs
[2023-02-23 02:24:49,260] {logging_mixin.py:115} INFO - [2023-02-23 02:24:49,260] {dag.py:2919} INFO - Setting next_dagrun for xray to 2023-02-20T00:00:58+00:00, run_after=2023-02-20T00:00:59+00:00
[2023-02-23 02:24:49,271] {processor.py:161} INFO - Processing /opt/airflow/dags/xray_test_dag.py took 0.079 seconds
[2023-02-23 02:25:19,328] {processor.py:153} INFO - Started process (PID=533) to work on /opt/airflow/dags/xray_test_dag.py
[2023-02-23 02:25:19,328] {processor.py:641} INFO - Processing file /opt/airflow/dags/xray_test_dag.py for tasks to queue
[2023-02-23 02:25:19,329] {logging_mixin.py:115} INFO - [2023-02-23 02:25:19,329] {dagbag.py:507} INFO - Filling up the DagBag from /opt/airflow/dags/xray_test_dag.py
[2023-02-23 02:25:19,345] {processor.py:651} INFO - DAG(s) dict_keys(['xray']) retrieved from /opt/airflow/dags/xray_test_dag.py
[2023-02-23 02:25:19,372] {logging_mixin.py:115} INFO - [2023-02-23 02:25:19,371] {dag.py:2371} INFO - Sync 1 DAGs
[2023-02-23 02:25:19,394] {logging_mixin.py:115} INFO - [2023-02-23 02:25:19,394] {dag.py:2919} INFO - Setting next_dagrun for xray to 2023-02-20T00:00:58+00:00, run_after=2023-02-20T00:00:59+00:00
[2023-02-23 02:25:19,417] {processor.py:161} INFO - Processing /opt/airflow/dags/xray_test_dag.py took 0.092 seconds
[2023-02-23 02:25:49,462] {processor.py:153} INFO - Started process (PID=538) to work on /opt/airflow/dags/xray_test_dag.py
[2023-02-23 02:25:49,463] {processor.py:641} INFO - Processing file /opt/airflow/dags/xray_test_dag.py for tasks to queue
[2023-02-23 02:25:49,464] {logging_mixin.py:115} INFO - [2023-02-23 02:25:49,463] {dagbag.py:507} INFO - Filling up the DagBag from /opt/airflow/dags/xray_test_dag.py
[2023-02-23 02:25:49,479] {processor.py:651} INFO - DAG(s) dict_keys(['xray']) retrieved from /opt/airflow/dags/xray_test_dag.py
[2023-02-23 02:25:49,506] {logging_mixin.py:115} INFO - [2023-02-23 02:25:49,506] {dag.py:2371} INFO - Sync 1 DAGs
[2023-02-23 02:25:49,528] {logging_mixin.py:115} INFO - [2023-02-23 02:25:49,528] {dag.py:2919} INFO - Setting next_dagrun for xray to 2023-02-20T00:00:58+00:00, run_after=2023-02-20T00:00:59+00:00
[2023-02-23 02:25:49,540] {processor.py:161} INFO - Processing /opt/airflow/dags/xray_test_dag.py took 0.080 seconds
[2023-02-23 02:26:19,608] {processor.py:153} INFO - Started process (PID=543) to work on /opt/airflow/dags/xray_test_dag.py
[2023-02-23 02:26:19,609] {processor.py:641} INFO - Processing file /opt/airflow/dags/xray_test_dag.py for tasks to queue
[2023-02-23 02:26:19,609] {logging_mixin.py:115} INFO - [2023-02-23 02:26:19,609] {dagbag.py:507} INFO - Filling up the DagBag from /opt/airflow/dags/xray_test_dag.py
[2023-02-23 02:26:19,626] {processor.py:651} INFO - DAG(s) dict_keys(['xray']) retrieved from /opt/airflow/dags/xray_test_dag.py
[2023-02-23 02:26:19,653] {logging_mixin.py:115} INFO - [2023-02-23 02:26:19,653] {dag.py:2371} INFO - Sync 1 DAGs
[2023-02-23 02:26:19,674] {logging_mixin.py:115} INFO - [2023-02-23 02:26:19,674] {dag.py:2919} INFO - Setting next_dagrun for xray to 2023-02-20T00:00:58+00:00, run_after=2023-02-20T00:00:59+00:00
[2023-02-23 02:26:19,697] {processor.py:161} INFO - Processing /opt/airflow/dags/xray_test_dag.py took 0.092 seconds
[2023-02-23 02:26:49,731] {processor.py:153} INFO - Started process (PID=548) to work on /opt/airflow/dags/xray_test_dag.py
[2023-02-23 02:26:49,731] {processor.py:641} INFO - Processing file /opt/airflow/dags/xray_test_dag.py for tasks to queue
[2023-02-23 02:26:49,732] {logging_mixin.py:115} INFO - [2023-02-23 02:26:49,732] {dagbag.py:507} INFO - Filling up the DagBag from /opt/airflow/dags/xray_test_dag.py
[2023-02-23 02:26:49,748] {processor.py:651} INFO - DAG(s) dict_keys(['xray']) retrieved from /opt/airflow/dags/xray_test_dag.py
[2023-02-23 02:26:49,776] {logging_mixin.py:115} INFO - [2023-02-23 02:26:49,776] {dag.py:2371} INFO - Sync 1 DAGs
[2023-02-23 02:26:49,797] {logging_mixin.py:115} INFO - [2023-02-23 02:26:49,797] {dag.py:2919} INFO - Setting next_dagrun for xray to 2023-02-20T00:00:58+00:00, run_after=2023-02-20T00:00:59+00:00
[2023-02-23 02:26:49,808] {processor.py:161} INFO - Processing /opt/airflow/dags/xray_test_dag.py took 0.080 seconds
[2023-02-23 02:27:19,890] {processor.py:153} INFO - Started process (PID=553) to work on /opt/airflow/dags/xray_test_dag.py
[2023-02-23 02:27:19,891] {processor.py:641} INFO - Processing file /opt/airflow/dags/xray_test_dag.py for tasks to queue
[2023-02-23 02:27:19,892] {logging_mixin.py:115} INFO - [2023-02-23 02:27:19,891] {dagbag.py:507} INFO - Filling up the DagBag from /opt/airflow/dags/xray_test_dag.py
[2023-02-23 02:27:19,907] {processor.py:651} INFO - DAG(s) dict_keys(['xray']) retrieved from /opt/airflow/dags/xray_test_dag.py
[2023-02-23 02:27:19,934] {logging_mixin.py:115} INFO - [2023-02-23 02:27:19,934] {dag.py:2371} INFO - Sync 1 DAGs
[2023-02-23 02:27:19,955] {logging_mixin.py:115} INFO - [2023-02-23 02:27:19,955] {dag.py:2919} INFO - Setting next_dagrun for xray to 2023-02-20T00:00:58+00:00, run_after=2023-02-20T00:00:59+00:00
[2023-02-23 02:27:19,979] {processor.py:161} INFO - Processing /opt/airflow/dags/xray_test_dag.py took 0.091 seconds
[2023-02-23 02:27:50,071] {processor.py:153} INFO - Started process (PID=558) to work on /opt/airflow/dags/xray_test_dag.py
[2023-02-23 02:27:50,072] {processor.py:641} INFO - Processing file /opt/airflow/dags/xray_test_dag.py for tasks to queue
[2023-02-23 02:27:50,072] {logging_mixin.py:115} INFO - [2023-02-23 02:27:50,072] {dagbag.py:507} INFO - Filling up the DagBag from /opt/airflow/dags/xray_test_dag.py
[2023-02-23 02:27:50,090] {processor.py:651} INFO - DAG(s) dict_keys(['xray']) retrieved from /opt/airflow/dags/xray_test_dag.py
[2023-02-23 02:27:50,118] {logging_mixin.py:115} INFO - [2023-02-23 02:27:50,117] {dag.py:2371} INFO - Sync 1 DAGs
[2023-02-23 02:27:50,139] {logging_mixin.py:115} INFO - [2023-02-23 02:27:50,139] {dag.py:2919} INFO - Setting next_dagrun for xray to 2023-02-20T00:00:58+00:00, run_after=2023-02-20T00:00:59+00:00
[2023-02-23 02:27:50,162] {processor.py:161} INFO - Processing /opt/airflow/dags/xray_test_dag.py took 0.093 seconds
[2023-02-23 02:28:20,253] {processor.py:153} INFO - Started process (PID=563) to work on /opt/airflow/dags/xray_test_dag.py
[2023-02-23 02:28:20,254] {processor.py:641} INFO - Processing file /opt/airflow/dags/xray_test_dag.py for tasks to queue
[2023-02-23 02:28:20,254] {logging_mixin.py:115} INFO - [2023-02-23 02:28:20,254] {dagbag.py:507} INFO - Filling up the DagBag from /opt/airflow/dags/xray_test_dag.py
[2023-02-23 02:28:20,270] {processor.py:651} INFO - DAG(s) dict_keys(['xray']) retrieved from /opt/airflow/dags/xray_test_dag.py
[2023-02-23 02:28:20,297] {logging_mixin.py:115} INFO - [2023-02-23 02:28:20,296] {dag.py:2371} INFO - Sync 1 DAGs
[2023-02-23 02:28:20,319] {logging_mixin.py:115} INFO - [2023-02-23 02:28:20,319] {dag.py:2919} INFO - Setting next_dagrun for xray to 2023-02-20T00:00:58+00:00, run_after=2023-02-20T00:00:59+00:00
[2023-02-23 02:28:20,341] {processor.py:161} INFO - Processing /opt/airflow/dags/xray_test_dag.py took 0.090 seconds
[2023-02-23 02:28:50,438] {processor.py:153} INFO - Started process (PID=568) to work on /opt/airflow/dags/xray_test_dag.py
[2023-02-23 02:28:50,438] {processor.py:641} INFO - Processing file /opt/airflow/dags/xray_test_dag.py for tasks to queue
[2023-02-23 02:28:50,439] {logging_mixin.py:115} INFO - [2023-02-23 02:28:50,439] {dagbag.py:507} INFO - Filling up the DagBag from /opt/airflow/dags/xray_test_dag.py
[2023-02-23 02:28:50,454] {processor.py:651} INFO - DAG(s) dict_keys(['xray']) retrieved from /opt/airflow/dags/xray_test_dag.py
[2023-02-23 02:28:50,481] {logging_mixin.py:115} INFO - [2023-02-23 02:28:50,481] {dag.py:2371} INFO - Sync 1 DAGs
[2023-02-23 02:28:50,502] {logging_mixin.py:115} INFO - [2023-02-23 02:28:50,502] {dag.py:2919} INFO - Setting next_dagrun for xray to 2023-02-20T00:00:58+00:00, run_after=2023-02-20T00:00:59+00:00
[2023-02-23 02:28:50,525] {processor.py:161} INFO - Processing /opt/airflow/dags/xray_test_dag.py took 0.090 seconds
[2023-02-23 02:29:20,567] {processor.py:153} INFO - Started process (PID=573) to work on /opt/airflow/dags/xray_test_dag.py
[2023-02-23 02:29:20,568] {processor.py:641} INFO - Processing file /opt/airflow/dags/xray_test_dag.py for tasks to queue
[2023-02-23 02:29:20,569] {logging_mixin.py:115} INFO - [2023-02-23 02:29:20,569] {dagbag.py:507} INFO - Filling up the DagBag from /opt/airflow/dags/xray_test_dag.py
[2023-02-23 02:29:20,586] {processor.py:651} INFO - DAG(s) dict_keys(['xray']) retrieved from /opt/airflow/dags/xray_test_dag.py
[2023-02-23 02:29:20,614] {logging_mixin.py:115} INFO - [2023-02-23 02:29:20,614] {dag.py:2371} INFO - Sync 1 DAGs
[2023-02-23 02:29:20,637] {logging_mixin.py:115} INFO - [2023-02-23 02:29:20,637] {dag.py:2919} INFO - Setting next_dagrun for xray to 2023-02-20T00:00:58+00:00, run_after=2023-02-20T00:00:59+00:00
[2023-02-23 02:29:20,661] {processor.py:161} INFO - Processing /opt/airflow/dags/xray_test_dag.py took 0.096 seconds
[2023-02-23 02:29:50,722] {processor.py:153} INFO - Started process (PID=578) to work on /opt/airflow/dags/xray_test_dag.py
[2023-02-23 02:29:50,723] {processor.py:641} INFO - Processing file /opt/airflow/dags/xray_test_dag.py for tasks to queue
[2023-02-23 02:29:50,723] {logging_mixin.py:115} INFO - [2023-02-23 02:29:50,723] {dagbag.py:507} INFO - Filling up the DagBag from /opt/airflow/dags/xray_test_dag.py
[2023-02-23 02:29:50,742] {processor.py:651} INFO - DAG(s) dict_keys(['xray']) retrieved from /opt/airflow/dags/xray_test_dag.py
[2023-02-23 02:29:50,772] {logging_mixin.py:115} INFO - [2023-02-23 02:29:50,772] {dag.py:2371} INFO - Sync 1 DAGs
[2023-02-23 02:29:50,795] {logging_mixin.py:115} INFO - [2023-02-23 02:29:50,794] {dag.py:2919} INFO - Setting next_dagrun for xray to 2023-02-20T00:00:58+00:00, run_after=2023-02-20T00:00:59+00:00
[2023-02-23 02:29:50,807] {processor.py:161} INFO - Processing /opt/airflow/dags/xray_test_dag.py took 0.088 seconds
[2023-02-23 02:30:17,856] {processor.py:153} INFO - Started process (PID=583) to work on /opt/airflow/dags/xray_test_dag.py
[2023-02-23 02:30:17,857] {processor.py:641} INFO - Processing file /opt/airflow/dags/xray_test_dag.py for tasks to queue
[2023-02-23 02:30:17,858] {logging_mixin.py:115} INFO - [2023-02-23 02:30:17,858] {dagbag.py:507} INFO - Filling up the DagBag from /opt/airflow/dags/xray_test_dag.py
[2023-02-23 02:30:17,882] {processor.py:651} INFO - DAG(s) dict_keys(['xray']) retrieved from /opt/airflow/dags/xray_test_dag.py
[2023-02-23 02:30:17,949] {logging_mixin.py:115} INFO - [2023-02-23 02:30:17,949] {dag.py:2371} INFO - Sync 1 DAGs
[2023-02-23 02:30:17,970] {logging_mixin.py:115} INFO - [2023-02-23 02:30:17,969] {dag.py:2919} INFO - Setting next_dagrun for xray to 2023-02-20T00:00:58+00:00, run_after=2023-02-20T00:00:59+00:00
[2023-02-23 02:30:17,987] {processor.py:161} INFO - Processing /opt/airflow/dags/xray_test_dag.py took 0.133 seconds
[2023-02-23 02:30:48,079] {processor.py:153} INFO - Started process (PID=588) to work on /opt/airflow/dags/xray_test_dag.py
[2023-02-23 02:30:48,079] {processor.py:641} INFO - Processing file /opt/airflow/dags/xray_test_dag.py for tasks to queue
[2023-02-23 02:30:48,080] {logging_mixin.py:115} INFO - [2023-02-23 02:30:48,080] {dagbag.py:507} INFO - Filling up the DagBag from /opt/airflow/dags/xray_test_dag.py
[2023-02-23 02:30:48,095] {processor.py:651} INFO - DAG(s) dict_keys(['xray']) retrieved from /opt/airflow/dags/xray_test_dag.py
[2023-02-23 02:30:48,122] {logging_mixin.py:115} INFO - [2023-02-23 02:30:48,122] {dag.py:2371} INFO - Sync 1 DAGs
[2023-02-23 02:30:48,148] {logging_mixin.py:115} INFO - [2023-02-23 02:30:48,147] {dag.py:2919} INFO - Setting next_dagrun for xray to 2023-02-20T00:00:58+00:00, run_after=2023-02-20T00:00:59+00:00
[2023-02-23 02:30:48,160] {processor.py:161} INFO - Processing /opt/airflow/dags/xray_test_dag.py took 0.084 seconds
[2023-02-23 02:31:18,189] {processor.py:153} INFO - Started process (PID=593) to work on /opt/airflow/dags/xray_test_dag.py
[2023-02-23 02:31:18,190] {processor.py:641} INFO - Processing file /opt/airflow/dags/xray_test_dag.py for tasks to queue
[2023-02-23 02:31:18,191] {logging_mixin.py:115} INFO - [2023-02-23 02:31:18,191] {dagbag.py:507} INFO - Filling up the DagBag from /opt/airflow/dags/xray_test_dag.py
[2023-02-23 02:31:18,209] {processor.py:651} INFO - DAG(s) dict_keys(['xray']) retrieved from /opt/airflow/dags/xray_test_dag.py
[2023-02-23 02:31:18,236] {logging_mixin.py:115} INFO - [2023-02-23 02:31:18,236] {dag.py:2371} INFO - Sync 1 DAGs
[2023-02-23 02:31:18,262] {logging_mixin.py:115} INFO - [2023-02-23 02:31:18,262] {dag.py:2919} INFO - Setting next_dagrun for xray to 2023-02-20T00:00:58+00:00, run_after=2023-02-20T00:00:59+00:00
[2023-02-23 02:31:18,276] {processor.py:161} INFO - Processing /opt/airflow/dags/xray_test_dag.py took 0.090 seconds
[2023-02-23 02:31:19,260] {processor.py:153} INFO - Started process (PID=598) to work on /opt/airflow/dags/xray_test_dag.py
[2023-02-23 02:31:19,260] {processor.py:641} INFO - Processing file /opt/airflow/dags/xray_test_dag.py for tasks to queue
[2023-02-23 02:31:19,261] {logging_mixin.py:115} INFO - [2023-02-23 02:31:19,261] {dagbag.py:507} INFO - Filling up the DagBag from /opt/airflow/dags/xray_test_dag.py
[2023-02-23 02:31:19,284] {processor.py:651} INFO - DAG(s) dict_keys(['xray']) retrieved from /opt/airflow/dags/xray_test_dag.py
[2023-02-23 02:31:19,309] {logging_mixin.py:115} INFO - [2023-02-23 02:31:19,309] {dag.py:2371} INFO - Sync 1 DAGs
[2023-02-23 02:31:19,330] {logging_mixin.py:115} INFO - [2023-02-23 02:31:19,330] {dag.py:2919} INFO - Setting next_dagrun for xray to 2023-02-20T00:00:58+00:00, run_after=2023-02-20T00:00:59+00:00
[2023-02-23 02:31:19,358] {processor.py:161} INFO - Processing /opt/airflow/dags/xray_test_dag.py took 0.100 seconds
[2023-02-23 02:31:49,404] {processor.py:153} INFO - Started process (PID=603) to work on /opt/airflow/dags/xray_test_dag.py
[2023-02-23 02:31:49,405] {processor.py:641} INFO - Processing file /opt/airflow/dags/xray_test_dag.py for tasks to queue
[2023-02-23 02:31:49,406] {logging_mixin.py:115} INFO - [2023-02-23 02:31:49,406] {dagbag.py:507} INFO - Filling up the DagBag from /opt/airflow/dags/xray_test_dag.py
[2023-02-23 02:31:49,422] {processor.py:651} INFO - DAG(s) dict_keys(['xray']) retrieved from /opt/airflow/dags/xray_test_dag.py
[2023-02-23 02:31:49,447] {logging_mixin.py:115} INFO - [2023-02-23 02:31:49,447] {dag.py:2371} INFO - Sync 1 DAGs
[2023-02-23 02:31:49,469] {logging_mixin.py:115} INFO - [2023-02-23 02:31:49,469] {dag.py:2919} INFO - Setting next_dagrun for xray to 2023-02-20T00:00:58+00:00, run_after=2023-02-20T00:00:59+00:00
[2023-02-23 02:31:49,492] {processor.py:161} INFO - Processing /opt/airflow/dags/xray_test_dag.py took 0.090 seconds
[2023-02-23 02:32:19,558] {processor.py:153} INFO - Started process (PID=608) to work on /opt/airflow/dags/xray_test_dag.py
[2023-02-23 02:32:19,559] {processor.py:641} INFO - Processing file /opt/airflow/dags/xray_test_dag.py for tasks to queue
[2023-02-23 02:32:19,559] {logging_mixin.py:115} INFO - [2023-02-23 02:32:19,559] {dagbag.py:507} INFO - Filling up the DagBag from /opt/airflow/dags/xray_test_dag.py
[2023-02-23 02:32:19,576] {processor.py:651} INFO - DAG(s) dict_keys(['xray']) retrieved from /opt/airflow/dags/xray_test_dag.py
[2023-02-23 02:32:19,603] {logging_mixin.py:115} INFO - [2023-02-23 02:32:19,603] {dag.py:2371} INFO - Sync 1 DAGs
[2023-02-23 02:32:19,624] {logging_mixin.py:115} INFO - [2023-02-23 02:32:19,624] {dag.py:2919} INFO - Setting next_dagrun for xray to 2023-02-20T00:00:58+00:00, run_after=2023-02-20T00:00:59+00:00
[2023-02-23 02:32:19,636] {processor.py:161} INFO - Processing /opt/airflow/dags/xray_test_dag.py took 0.080 seconds
[2023-02-23 02:32:49,688] {processor.py:153} INFO - Started process (PID=613) to work on /opt/airflow/dags/xray_test_dag.py
[2023-02-23 02:32:49,689] {processor.py:641} INFO - Processing file /opt/airflow/dags/xray_test_dag.py for tasks to queue
[2023-02-23 02:32:49,690] {logging_mixin.py:115} INFO - [2023-02-23 02:32:49,690] {dagbag.py:507} INFO - Filling up the DagBag from /opt/airflow/dags/xray_test_dag.py
[2023-02-23 02:32:49,708] {processor.py:651} INFO - DAG(s) dict_keys(['xray']) retrieved from /opt/airflow/dags/xray_test_dag.py
[2023-02-23 02:32:49,736] {logging_mixin.py:115} INFO - [2023-02-23 02:32:49,736] {dag.py:2371} INFO - Sync 1 DAGs
[2023-02-23 02:32:49,760] {logging_mixin.py:115} INFO - [2023-02-23 02:32:49,760] {dag.py:2919} INFO - Setting next_dagrun for xray to 2023-02-20T00:00:58+00:00, run_after=2023-02-20T00:00:59+00:00
[2023-02-23 02:32:49,772] {processor.py:161} INFO - Processing /opt/airflow/dags/xray_test_dag.py took 0.086 seconds
[2023-02-23 02:33:19,829] {processor.py:153} INFO - Started process (PID=618) to work on /opt/airflow/dags/xray_test_dag.py
[2023-02-23 02:33:19,829] {processor.py:641} INFO - Processing file /opt/airflow/dags/xray_test_dag.py for tasks to queue
[2023-02-23 02:33:19,830] {logging_mixin.py:115} INFO - [2023-02-23 02:33:19,830] {dagbag.py:507} INFO - Filling up the DagBag from /opt/airflow/dags/xray_test_dag.py
[2023-02-23 02:33:19,846] {processor.py:651} INFO - DAG(s) dict_keys(['xray']) retrieved from /opt/airflow/dags/xray_test_dag.py
[2023-02-23 02:33:19,873] {logging_mixin.py:115} INFO - [2023-02-23 02:33:19,873] {dag.py:2371} INFO - Sync 1 DAGs
[2023-02-23 02:33:19,894] {logging_mixin.py:115} INFO - [2023-02-23 02:33:19,894] {dag.py:2919} INFO - Setting next_dagrun for xray to 2023-02-20T00:00:58+00:00, run_after=2023-02-20T00:00:59+00:00
[2023-02-23 02:33:19,918] {processor.py:161} INFO - Processing /opt/airflow/dags/xray_test_dag.py took 0.091 seconds
[2023-02-23 02:33:49,967] {processor.py:153} INFO - Started process (PID=623) to work on /opt/airflow/dags/xray_test_dag.py
[2023-02-23 02:33:49,967] {processor.py:641} INFO - Processing file /opt/airflow/dags/xray_test_dag.py for tasks to queue
[2023-02-23 02:33:49,968] {logging_mixin.py:115} INFO - [2023-02-23 02:33:49,968] {dagbag.py:507} INFO - Filling up the DagBag from /opt/airflow/dags/xray_test_dag.py
[2023-02-23 02:33:49,984] {processor.py:651} INFO - DAG(s) dict_keys(['xray']) retrieved from /opt/airflow/dags/xray_test_dag.py
[2023-02-23 02:33:50,011] {logging_mixin.py:115} INFO - [2023-02-23 02:33:50,010] {dag.py:2371} INFO - Sync 1 DAGs
[2023-02-23 02:33:50,033] {logging_mixin.py:115} INFO - [2023-02-23 02:33:50,033] {dag.py:2919} INFO - Setting next_dagrun for xray to 2023-02-20T00:00:58+00:00, run_after=2023-02-20T00:00:59+00:00
[2023-02-23 02:33:50,044] {processor.py:161} INFO - Processing /opt/airflow/dags/xray_test_dag.py took 0.079 seconds
[2023-02-23 02:34:20,130] {processor.py:153} INFO - Started process (PID=628) to work on /opt/airflow/dags/xray_test_dag.py
[2023-02-23 02:34:20,130] {processor.py:641} INFO - Processing file /opt/airflow/dags/xray_test_dag.py for tasks to queue
[2023-02-23 02:34:20,131] {logging_mixin.py:115} INFO - [2023-02-23 02:34:20,131] {dagbag.py:507} INFO - Filling up the DagBag from /opt/airflow/dags/xray_test_dag.py
[2023-02-23 02:34:20,148] {processor.py:651} INFO - DAG(s) dict_keys(['xray']) retrieved from /opt/airflow/dags/xray_test_dag.py
[2023-02-23 02:34:20,174] {logging_mixin.py:115} INFO - [2023-02-23 02:34:20,174] {dag.py:2371} INFO - Sync 1 DAGs
[2023-02-23 02:34:20,197] {logging_mixin.py:115} INFO - [2023-02-23 02:34:20,196] {dag.py:2919} INFO - Setting next_dagrun for xray to 2023-02-20T00:00:58+00:00, run_after=2023-02-20T00:00:59+00:00
[2023-02-23 02:34:20,220] {processor.py:161} INFO - Processing /opt/airflow/dags/xray_test_dag.py took 0.093 seconds
[2023-02-23 02:34:50,314] {processor.py:153} INFO - Started process (PID=633) to work on /opt/airflow/dags/xray_test_dag.py
[2023-02-23 02:34:50,314] {processor.py:641} INFO - Processing file /opt/airflow/dags/xray_test_dag.py for tasks to queue
[2023-02-23 02:34:50,315] {logging_mixin.py:115} INFO - [2023-02-23 02:34:50,315] {dagbag.py:507} INFO - Filling up the DagBag from /opt/airflow/dags/xray_test_dag.py
[2023-02-23 02:34:50,333] {processor.py:651} INFO - DAG(s) dict_keys(['xray']) retrieved from /opt/airflow/dags/xray_test_dag.py
[2023-02-23 02:34:50,360] {logging_mixin.py:115} INFO - [2023-02-23 02:34:50,360] {dag.py:2371} INFO - Sync 1 DAGs
[2023-02-23 02:34:50,383] {logging_mixin.py:115} INFO - [2023-02-23 02:34:50,382] {dag.py:2919} INFO - Setting next_dagrun for xray to 2023-02-20T00:00:58+00:00, run_after=2023-02-20T00:00:59+00:00
[2023-02-23 02:34:50,406] {processor.py:161} INFO - Processing /opt/airflow/dags/xray_test_dag.py took 0.094 seconds
[2023-02-23 02:35:20,503] {processor.py:153} INFO - Started process (PID=638) to work on /opt/airflow/dags/xray_test_dag.py
[2023-02-23 02:35:20,503] {processor.py:641} INFO - Processing file /opt/airflow/dags/xray_test_dag.py for tasks to queue
[2023-02-23 02:35:20,504] {logging_mixin.py:115} INFO - [2023-02-23 02:35:20,504] {dagbag.py:507} INFO - Filling up the DagBag from /opt/airflow/dags/xray_test_dag.py
[2023-02-23 02:35:20,533] {processor.py:651} INFO - DAG(s) dict_keys(['xray']) retrieved from /opt/airflow/dags/xray_test_dag.py
[2023-02-23 02:35:20,562] {logging_mixin.py:115} INFO - [2023-02-23 02:35:20,562] {dag.py:2371} INFO - Sync 1 DAGs
[2023-02-23 02:35:20,591] {logging_mixin.py:115} INFO - [2023-02-23 02:35:20,591] {dag.py:2919} INFO - Setting next_dagrun for xray to 2023-02-20T00:00:58+00:00, run_after=2023-02-20T00:00:59+00:00
[2023-02-23 02:35:20,604] {processor.py:161} INFO - Processing /opt/airflow/dags/xray_test_dag.py took 0.103 seconds
[2023-02-23 02:35:50,699] {processor.py:153} INFO - Started process (PID=643) to work on /opt/airflow/dags/xray_test_dag.py
[2023-02-23 02:35:50,699] {processor.py:641} INFO - Processing file /opt/airflow/dags/xray_test_dag.py for tasks to queue
[2023-02-23 02:35:50,700] {logging_mixin.py:115} INFO - [2023-02-23 02:35:50,700] {dagbag.py:507} INFO - Filling up the DagBag from /opt/airflow/dags/xray_test_dag.py
[2023-02-23 02:35:50,717] {processor.py:651} INFO - DAG(s) dict_keys(['xray']) retrieved from /opt/airflow/dags/xray_test_dag.py
[2023-02-23 02:35:50,743] {logging_mixin.py:115} INFO - [2023-02-23 02:35:50,743] {dag.py:2371} INFO - Sync 1 DAGs
[2023-02-23 02:35:50,766] {logging_mixin.py:115} INFO - [2023-02-23 02:35:50,766] {dag.py:2919} INFO - Setting next_dagrun for xray to 2023-02-20T00:00:58+00:00, run_after=2023-02-20T00:00:59+00:00
[2023-02-23 02:35:50,789] {processor.py:161} INFO - Processing /opt/airflow/dags/xray_test_dag.py took 0.093 seconds
[2023-02-23 02:36:20,892] {processor.py:153} INFO - Started process (PID=648) to work on /opt/airflow/dags/xray_test_dag.py
[2023-02-23 02:36:20,892] {processor.py:641} INFO - Processing file /opt/airflow/dags/xray_test_dag.py for tasks to queue
[2023-02-23 02:36:20,893] {logging_mixin.py:115} INFO - [2023-02-23 02:36:20,893] {dagbag.py:507} INFO - Filling up the DagBag from /opt/airflow/dags/xray_test_dag.py
[2023-02-23 02:36:20,910] {processor.py:651} INFO - DAG(s) dict_keys(['xray']) retrieved from /opt/airflow/dags/xray_test_dag.py
[2023-02-23 02:36:20,936] {logging_mixin.py:115} INFO - [2023-02-23 02:36:20,936] {dag.py:2371} INFO - Sync 1 DAGs
[2023-02-23 02:36:20,957] {logging_mixin.py:115} INFO - [2023-02-23 02:36:20,957] {dag.py:2919} INFO - Setting next_dagrun for xray to 2023-02-20T00:00:58+00:00, run_after=2023-02-20T00:00:59+00:00
[2023-02-23 02:36:20,968] {processor.py:161} INFO - Processing /opt/airflow/dags/xray_test_dag.py took 0.080 seconds
[2023-02-23 02:36:51,060] {processor.py:153} INFO - Started process (PID=653) to work on /opt/airflow/dags/xray_test_dag.py
[2023-02-23 02:36:51,060] {processor.py:641} INFO - Processing file /opt/airflow/dags/xray_test_dag.py for tasks to queue
[2023-02-23 02:36:51,061] {logging_mixin.py:115} INFO - [2023-02-23 02:36:51,061] {dagbag.py:507} INFO - Filling up the DagBag from /opt/airflow/dags/xray_test_dag.py
[2023-02-23 02:36:51,077] {processor.py:651} INFO - DAG(s) dict_keys(['xray']) retrieved from /opt/airflow/dags/xray_test_dag.py
[2023-02-23 02:36:51,104] {logging_mixin.py:115} INFO - [2023-02-23 02:36:51,103] {dag.py:2371} INFO - Sync 1 DAGs
[2023-02-23 02:36:51,125] {logging_mixin.py:115} INFO - [2023-02-23 02:36:51,125] {dag.py:2919} INFO - Setting next_dagrun for xray to 2023-02-20T00:00:58+00:00, run_after=2023-02-20T00:00:59+00:00
[2023-02-23 02:36:51,148] {processor.py:161} INFO - Processing /opt/airflow/dags/xray_test_dag.py took 0.091 seconds
[2023-02-23 02:37:21,241] {processor.py:153} INFO - Started process (PID=658) to work on /opt/airflow/dags/xray_test_dag.py
[2023-02-23 02:37:21,241] {processor.py:641} INFO - Processing file /opt/airflow/dags/xray_test_dag.py for tasks to queue
[2023-02-23 02:37:21,242] {logging_mixin.py:115} INFO - [2023-02-23 02:37:21,242] {dagbag.py:507} INFO - Filling up the DagBag from /opt/airflow/dags/xray_test_dag.py
[2023-02-23 02:37:21,259] {processor.py:651} INFO - DAG(s) dict_keys(['xray']) retrieved from /opt/airflow/dags/xray_test_dag.py
[2023-02-23 02:37:21,286] {logging_mixin.py:115} INFO - [2023-02-23 02:37:21,286] {dag.py:2371} INFO - Sync 1 DAGs
[2023-02-23 02:37:21,309] {logging_mixin.py:115} INFO - [2023-02-23 02:37:21,309] {dag.py:2919} INFO - Setting next_dagrun for xray to 2023-02-20T00:00:58+00:00, run_after=2023-02-20T00:00:59+00:00
[2023-02-23 02:37:21,332] {processor.py:161} INFO - Processing /opt/airflow/dags/xray_test_dag.py took 0.094 seconds
[2023-02-23 02:37:51,425] {processor.py:153} INFO - Started process (PID=666) to work on /opt/airflow/dags/xray_test_dag.py
[2023-02-23 02:37:51,426] {processor.py:641} INFO - Processing file /opt/airflow/dags/xray_test_dag.py for tasks to queue
[2023-02-23 02:37:51,427] {logging_mixin.py:115} INFO - [2023-02-23 02:37:51,427] {dagbag.py:507} INFO - Filling up the DagBag from /opt/airflow/dags/xray_test_dag.py
[2023-02-23 02:37:51,445] {processor.py:651} INFO - DAG(s) dict_keys(['xray']) retrieved from /opt/airflow/dags/xray_test_dag.py
[2023-02-23 02:37:51,475] {logging_mixin.py:115} INFO - [2023-02-23 02:37:51,475] {dag.py:2371} INFO - Sync 1 DAGs
[2023-02-23 02:37:51,505] {logging_mixin.py:115} INFO - [2023-02-23 02:37:51,505] {dag.py:2919} INFO - Setting next_dagrun for xray to 2023-02-20T00:00:58+00:00, run_after=2023-02-20T00:00:59+00:00
[2023-02-23 02:37:51,532] {processor.py:161} INFO - Processing /opt/airflow/dags/xray_test_dag.py took 0.109 seconds
